Workbook

Sheet ዕቁብ
A1: ዕጣ ቁጥር | B1: ስም | C1: ክፍያ መጠን | D1: =ROUND(Sheet3!$C$1,0) -> 183 | E1: 1 | F1: =E1+1 -> 2 | G1: =F1+1 -> 3 | H1: =G1+1 -> 4 | I1: =H1+1 -> 5 | J1: =I1+1 -> 6 | K1: =J1+1 -> 7 | L1: =K1+1 -> 8 | M1: =L1+1 -> 9 | ... DR1: =DQ1+1 -> 118
D2: =113*21000*D1 -> 434259000 | E2: =F2-7 -> 44871 | F2: =G2-7 -> 44878 | G2: =H2-7 -> 44885 | H2: =I2-7 -> 44892 | I2: =J2-7 -> 44899 | J2: =K2-7 -> 44906 | K2: =L2-7 -> 44913 | L2: =M2-7 -> 44920 | ... BF2: =BG2-7 -> 45242 | BG2: 45249 | BH2: =BG2+7 -> 45256 | BI2: =BH2+7 -> 45263 | BJ2: =BI2+7 -> 45270 | BK2: =BJ2+7 -> 45277 | BL2: =BK2+7 -> 45284 | BM2: =BL2+7 -> 45291 | BN2: =BM2+7 -> 45298 | BO2: =BN2+7 -> 45305 | ... DR2: =DQ2+7 -> 45690
D3: =SUM(E3:DR4) -> 230107500 | E3: =SUM(E6:E138) -> 2247000 | F3: =SUM(F6:F138) -> 2236500 | G3: =SUM(G6:G138) -> 2236500 | H3: =SUM(H6:H138) -> 2236500 | I3: =SUM(I6:I138) -> 2236500 | J3: =SUM(J6:J138) -> 2236500 | K3: =SUM(K6:K138) -> 2236500 | L3: =SUM(L6:L138) -> 2236500 | ... DR3: =SUM(DR6:DR138) -> 0
D4: =D2-D3 -> 204151500
D5: =D3/D2 -> 0.52988539 | E5: =E3/(113*21000) -> 0.94690265 | F5: =F3/(113*21000) -> 0.94247788 | G5: =G3/(113*21000) -> 0.94247788 | H5: =H3/(113*21000) -> 0.94247788 | I5: =I3/(113*21000) -> 0.94247788 | J5: =J3/(113*21000) -> 0.94247788 | K5: =K3/(113*21000) -> 0.94247788 | L5: =L3/(113*21000) -> 0.94247788 | ... DR5: =DR3/(113*21000) -> 0
A6: 1 | B6: መስፍን ሀ/ማሪያም | C6: 21000 | D6: =Sheet3!C2 -> 103 | E6: 21000 | F6: 21000 | G6: 21000 | H6: 21000 | I6: 21000 | J6: 21000 | K6: 21000 | L6: 21000 | M6: 21000 | N6: 21000 | O6: 21000 | P6: 21000 | Q6: 21000 | R6: 21000 | S6: 21000 | T6: 21000 | U6: 21000 | V6: 21000 | W6: 21000 | X6: 0 | Y6: 21000 | Z6: 42000 | AA6: 21000 | AB6: 21000 | AC6: 21000 | AD6: 21000 | AE6: 21000 | AF6: 21000 | AG6: 21000 | AH6: 21000 | AI6: 0 | AJ6: 42000 | AK6: 0 | AL6: 42000 | AM6: 21000 | AN6: 21000 | AO6: 21000 | AP6: 21000 | AQ6: 21000 | AR6: 0 | AS6: 0 | AT6: 0 | AU6: 84000 | AV6: 21000 | AW6: 21000 | AX6: 21000 | AY6: 0 | AZ6: 21000 | BA6: 21000 | BB6: 0 | BC6: 42000 | BD6: 21000 | BE6: 42000 | BF6: 21000 | BG6: 0 | BH6: 21000 | BI6: 42000 | BJ6: 0 | BK6: 42000 | BL6: 0 | BM6: 0 | BN6: 0 | BO6: 84000 | BP6: 0 | BR6: 63000 | BS6: 0 | BT6: 42000 | BU6: 21000 | BV6: 0 | BW6: 42000 | BX6: 0 | BY6: 0 | BZ6: 42000 | CA6: 21000 | CB6: 0 | CC6: 0 | CD6: 0 | CE6: 0 | CF6: 0 | CG6: 42000 | CH6: 0 | CI6: 84000 | CJ6: 0 | CK6: 105000 | CL6: 21000 | CM6: 21000 | CN6: 21000 | CO6: 0 | CP6: 0 | CQ6: 21000 | CR6: 42000 | CS6: 42000 | CT6: 21000 | CU6: 0 | CV6: 0 | CW6: 21000 | CX6: 21000 | CY6: 42000 | CZ6: 0 | DA6: 0 | DB6: 0 | DC6: 21000 | DD6: 42000 | DE6: 21000 | DF6: 21000
A7: 2 | B7: ዓማኑኤል አላሮ | C7: 21000 | D7: =Sheet3!C3 -> 108 | E7: 21000 | F7: 21000 | G7: 21000 | H7: 21000 | I7: 21000 | J7: 21000 | K7: 21000 | L7: 21000 | M7: 21000 | N7: 21000 | O7: 21000 | P7: 21000 | Q7: 21000 | R7: 21000 | S7: 21000 | T7: 21000 | U7: 21000 | V7: 21000 | W7: 21000 | X7: 21000 | Y7: 21000 | Z7: 21000 | AA7: 21000 | AB7: 21000 | AC7: 21000 | AD7: 21000 | AE7: 21000 | AF7: 21000 | AG7: 21000 | AH7: 21000 | AI7: 21000 | AJ7: 21000 | AK7: 21000 | AL7: 21000 | AM7: 21000 | AN7: 21000 | AO7: 21000 | AP7: 21000 | AQ7: 21000 | AR7: 21000 | AS7: 21000 | AT7: 21000 | AU7: 21000 | AV7: 21000 | AW7: 21000 | AX7: 21000 | AY7: 21000 | AZ7: 21000 | BA7: 21000 | BB7: 21000 | BC7: 21000 | BD7: 21000 | BE7: 21000 | BF7: 21000 | BG7: 21000 | BH7: 21000 | BI7: 21000 | BJ7: 21000 | BK7: 21000 | BL7: 21000 | BM7: 21000 | BN7: 21000 | BO7: 21000 | BP7: 21000 | BQ7: 21000 | BR7: 21000 | BS7: 21000 | BT7: 21000 | BU7: 21000 | BV7: 21000 | BW7: 21000 | BX7: 21000 | BY7: 21000 | BZ7: 21000 | CA7: 21000 | CB7: 21000 | CC7: 21000 | CD7: 21000 | CE7: 21000 | CF7: 21000 | CG7: 21000 | CH7: 21000 | CI7: 21000 | CJ7: 21000 | CK7: 21000 | CL7: 21000 | CM7: 21000 | CN7: 21000 | CO7: 21000 | CP7: 21000 | CQ7: 21000 | CR7: 21000 | CS7: 21000 | CT7: 21000 | CU7: 21000 | CV7: 21000 | CW7: 21000 | CX7: 21000 | CY7: 21000 | CZ7: 21000 | DA7: 21000 | DB7: 21000 | DC7: 21000 | DD7: 21000 | DE7: 21000 | DF7: 21000 | DG7: 21000 | DH7: 21000
A8: 3 | B8: ብርሃኑ ማሩ | C8: 21000 | D8: =Sheet3!C4 -> 107 | E8: 21000 | F8: 21000 | G8: 21000 | H8: 21000 | I8: 21000 | J8: 21000 | K8: 21000 | L8: 21000 | M8: 21000 | N8: 21000 | O8: 21000 | P8: 21000 | Q8: 21000 | R8: 21000 | S8: 21000 | T8: 21000 | U8: 21000 | V8: 21000 | W8: 21000 | X8: 21000 | Y8: 21000 | Z8: 21000 | AA8: 21000 | AB8: 21000 | AC8: 21000 | AD8: 21000 | AE8: 21000 | AF8: 21000 | AG8: 21000 | AH8: 21000 | AI8: 21000 | AJ8: 21000 | AK8: 21000 | AL8: 21000 | AM8: 21000 | AN8: 21000 | AO8: 21000 | AP8: 21000 | AQ8: 21000 | AR8: 21000 | AS8: 21000 | AT8: 21000 | AU8: 21000 | AV8: 21000 | AW8: 21000 | AX8: 21000 | AY8: 21000 | AZ8: 21000 | BA8: 21000 | BB8: 21000 | BC8: 21000 | BD8: 21000 | BE8: 21000 | BF8: 21000 | BG8: 21000 | BH8: 21000 | BI8: 21000 | BJ8: 21000 | BK8: 21000 | BL8: 21000 | BM8: 21000 | BN8: 21000 | BO8: 0 | BP8: 21000 | BQ8: 21000 | BR8: 21000 | BS8: 21000 | BT8: 21000 | BU8: 21000 | BV8: 21000 | BW8: 21000 | BX8: 21000 | BY8: 21000 | BZ8: 21000 | CA8: 21000 | CB8: 21000 | CC8: 21000 | CD8: 21000 | CE8: 21000 | CF8: 21000 | CG8: 21000 | CH8: 21000 | CI8: 21000 | CJ8: 21000 | CK8: 21000 | CL8: 21000 | CM8: 21000 | CN8: 21000 | CO8: 21000 | CP8: 21000 | CQ8: 21000 | CR8: 21000 | CS8: 21000 | CT8: 21000 | CU8: 21000 | CV8: 21000 | CW8: 21000 | CX8: 21000 | CY8: 21000 | CZ8: 21000 | DA8: 21000 | DB8: 21000 | DC8: 21000 | DD8: 21000 | DE8: 0 | DF8: 42000 | DG8: 21000 | DH8: 21000
A9: 4 | B9: ከፈለኝ ፃዲቁ | C9: 21000 | D9: =Sheet3!C5 -> 0 | E9: 0 | F9: 0 | G9: 0 | H9: 0 | I9: 0 | J9: 0 | K9: 0 | L9: 0 | M9: 0 | N9: 0 | O9: 0 | P9: 0 | Q9: 0 | R9: 0 | S9: 0 | T9: 0 | U9: 0 | V9: 0 | W9: 0 | X9: 0 | Y9: 0 | Z9: 0 | AA9: 0 | AB9: 0 | AC9: 0 | AD9: 0 | AE9: 0 | AF9: 0 | AG9: 0 | AH9: 0 | AI9: 0 | AJ9: 0 | AK9: 0 | AL9: 0 | AM9: 0 | AN9: 0 | AO9: 0 | AP9: 0 | AQ9: 0 | AR9: 0 | AS9: 0 | AT9: 0 | AU9: 0 | AV9: 0 | AW9: 0 | AX9: 0 | AY9: 0 | AZ9: 0 | BA9: 0 | BB9: 0 | BC9: 0 | BD9: 0 | BE9: 0 | BF9: 0 | BG9: 0 | BH9: 0 | BI9: 0 | BJ9: 0 | BK9: 0 | BL9: 0 | BM9: 0 | BN9: 0 | BO9: 0 | BP9: 0 | BQ9: 0 | BR9: 0 | BS9: 0 | BT9: 0 | BV9: 0 | BW9: 0 | BX9: 0 | BY9: 0 | BZ9: 0 | CA9: 0 | CB9: 0 | CC9: 0 | CD9: 0 | CE9: 0 | CF9: 0 | CG9: 0 | CH9: 0 | CI9: 0 | CJ9: 0 | CK9: 0 | CL9: 0 | CM9: 0 | CN9: 0 | CO9: 0 | CP9: 0 | CQ9: 0 | CR9: 0 | CS9: 0 | CT9: 0 | CU9: 0 | CV9: 0 | CW9: 0 | CX9: 0 | CY9: 0 | CZ9: 0 | DA9: 0 | DB9: 0 | DC9: 0 | DD9: 0 | DE9: 0 | DF9: 0
A10: 5 | B10: አስፈው ወርጂ | C10: 21000 | D10: =Sheet3!C6 -> 108 | E10: 21000 | F10: 21000 | G10: 21000 | H10: 21000 | I10: 21000 | J10: 21000 | K10: 21000 | L10: 21000 | M10: 21000 | N10: 21000 | O10: 21000 | P10: 21000 | Q10: 21000 | R10: 21000 | S10: 21000 | T10: 21000 | U10: 21000 | V10: 21000 | W10: 21000 | X10: 21000 | Y10: 21000 | Z10: 21000 | AA10: 21000 | AB10: 21000 | AC10: 21000 | AD10: 21000 | AE10: 21000 | AF10: 21000 | AG10: 21000 | AH10: 21000 | AI10: 0 | AJ10: 42000 | AK10: 21000 | AL10: 21000 | AM10: 21000 | AN10: 21000 | AO10: 21000 | AP10: 21000 | AQ10: 21000 | AR10: 21000 | AS10: 21000 | AT10: 21000 | AU10: 21000 | AV10: 0 | AW10: 42000 | AX10: 21000 | AY10: 21000 | AZ10: 21000 | BA10: 21000 | BB10: 21000 | BC10: 21000 | BD10: 21000 | BE10: 21000 | BF10: 21000 | BG10: 21000 | BH10: 21000 | BI10: 21000 | BJ10: 21000 | BK10: 21000 | BL10: 0 | BM10: 42000 | BN10: 21000 | BO10: 21000 | BP10: 0 | BQ10: 42000 | BR10: 21000 | BS10: 21000 | BT10: 21000 | BU10: 21000 | BV10: 21000 | BW10: 21000 | BX10: 21000 | BY10: 21000 | BZ10: 21000 | CA10: 21000 | CB10: 21000 | CC10: 21000 | CD10: 21000 | CE10: 21000 | CF10: 21000 | CG10: 21000 | CH10: 0 | CI10: 42000 | CJ10: 21000 | CK10: 21000 | CL10: 21000 | CM10: 21000 | CN10: 21000 | CO10: 21000 | CP10: 21000 | CQ10: 0 | CR10: 42000 | CS10: 21000 | CT10: 0 | CU10: 0 | CV10: 63000 | CW10: 21000 | CX10: 21000 | CY10: 0 | CZ10: 42000 | DA10: 21000 | DB10: 0 | DC10: 42000 | DD10: 0 | DE10: 0 | DF10: 63000 | DH10: 42000
A11: 6 | B11: ከተማ ለማ | C11: 21000 | D11: =Sheet3!C7 -> 107 | E11: 21000 | F11: 21000 | G11: 21000 | H11: 21000 | I11: 21000 | J11: 21000 | K11: 21000 | L11: 21000 | M11: 21000 | N11: 21000 | O11: 21000 | P11: 21000 | Q11: 21000 | R11: 21000 | S11: 21000 | T11: 21000 | U11: 21000 | V11: 21000 | W11: 21000 | X11: 21000 | Y11: 21000 | Z11: 21000 | AA11: 21000 | AB11: 21000 | AC11: 21000 | AD11: 21000 | AE11: 21000 | AF11: 21000 | AG11: 21000 | AH11: 21000 | AI11: 21000 | AJ11: 21000 | AK11: 21000 | AL11: 21000 | AM11: 21000 | AN11: 21000 | AO11: 21000 | AP11: 21000 | AQ11: 21000 | AR11: 21000 | AS11: 21000 | AT11: 21000 | AU11: 21000 | AV11: 21000 | AW11: 21000 | AX11: 21000 | AY11: 21000 | AZ11: 21000 | BA11: 21000 | BB11: 21000 | BC11: 21000 | BD11: 21000 | BE11: 21000 | BF11: 21000 | BG11: 21000 | BH11: 21000 | BI11: 21000 | BJ11: 21000 | BK11: 21000 | BL11: 21000 | BM11: 21000 | BN11: 21000 | BO11: 21000 | BP11: 21000 | BQ11: 21000 | BR11: 21000 | BS11: 21000 | BT11: 21000 | BU11: 21000 | BV11: 21000 | BW11: 21000 | BX11: 21000 | BY11: 21000 | BZ11: 21000 | CA11: 21000 | CB11: 21000 | CC11: 21000 | CD11: 0 | CE11: 42000 | CF11: 21000 | CG11: 21000 | CH11: 21000 | CI11: 21000 | CJ11: 0 | CK11: 42000 | CL11: 21000 | CM11: 21000 | CN11: 21000 | CO11: 21000 | CP11: 21000 | CQ11: 21000 | CR11: 21000 | CS11: 21000 | CT11: 21000 | CU11: 0 | CV11: 21000 | CW11: 21000 | CX11: 21000 | CY11: 21000 | CZ11: 21000 | DA11: 21000 | DB11: 21000 | DC11: 21000 | DD11: 21000 | DE11: 21000 | DF11: 21000 | DG11: 21000 | DH11: 21000
A12: 7 | B12: ጥላነሽ ከበደ | C12: 21000 | D12: =Sheet3!C8 -> 108 | E12: 21000 | F12: 21000 | G12: 21000 | H12: 21000 | I12: 21000 | J12: 21000 | K12: 21000 | L12: 21000 | M12: 21000 | N12: 21000 | O12: 21000 | P12: 21000 | Q12: 21000 | R12: 21000 | S12: 21000 | T12: 21000 | U12: 21000 | V12: 21000 | W12: 21000 | X12: 21000 | Y12: 21000 | Z12: 21000 | AA12: 21000 | AB12: 21000 | AC12: 21000 | AD12: 21000 | AE12: 21000 | AF12: 21000 | AG12: 21000 | AH12: 21000 | AI12: 21000 | AJ12: 21000 | AK12: 21000 | AL12: 21000 | AM12: 21000 | AN12: 21000 | AO12: 21000 | AP12: 0 | AQ12: 42000 | AR12: 21000 | AS12: 21000 | AT12: 21000 | AU12: 21000 | AV12: 21000 | AW12: 21000 | AX12: 21000 | AY12: 21000 | AZ12: 21000 | BA12: 21000 | BB12: 21000 | BC12: 21000 | BD12: 21000 | BE12: 21000 | BF12: 21000 | BG12: 21000 | BH12: 21000 | BI12: 21000 | BJ12: 21000 | BK12: 21000 | BL12: 21000 | BM12: 21000 | BN12: 0 | BO12: 42000 | BP12: 21000 | BQ12: 21000 | BR12: 21000 | BS12: 21000 | BT12: 21000 | BU12: 21000 | BV12: 21000 | BW12: 21000 | BX12: 21000 | BY12: 21000 | BZ12: 21000 | CA12: 21000 | CB12: 21000 | CC12: 21000 | CD12: 21000 | CE12: 0 | CF12: 42000 | CG12: 21000 | CH12: 21000 | CI12: 21000 | CJ12: 21000 | CK12: 21000 | CL12: 21000 | CM12: 21000 | CN12: 21000 | CO12: 21000 | CP12: 21000 | CQ12: 21000 | CR12: 21000 | CS12: 21000 | CT12: 21000 | CU12: 21000 | CV12: 21000 | CW12: 21000 | CX12: 21000 | CY12: 21000 | CZ12: 21000 | DA12: 21000 | DB12: 21000 | DC12: 21000 | DD12: 21000 | DE12: 21000 | DF12: 21000 | DG12: 21000 | DH12: 21000
A13: 8 | B13: ሲሳይ ባህሩ | C13: 21000 | D13: =Sheet3!C9 -> 108 | E13: 21000 | F13: 21000 | G13: 21000 | H13: 21000 | I13: 21000 | J13: 21000 | K13: 21000 | L13: 21000 | M13: 21000 | N13: 21000 | O13: 21000 | P13: 21000 | Q13: 21000 | R13: 21000 | S13: 21000 | T13: 21000 | U13: 21000 | V13: 21000 | W13: 21000 | X13: 21000 | Y13: 21000 | Z13: 21000 | AA13: 21000 | AB13: 21000 | AC13: 21000 | AD13: 21000 | AE13: 21000 | AF13: 21000 | AG13: 21000 | AH13: 21000 | AI13: 21000 | AJ13: 21000 | AK13: 21000 | AL13: 21000 | AM13: 21000 | AN13: 21000 | AO13: 21000 | AP13: 21000 | AQ13: 21000 | AR13: 21000 | AS13: 21000 | AT13: 21000 | AU13: 21000 | AV13: 21000 | AW13: 21000 | AX13: 21000 | AY13: 21000 | AZ13: 21000 | BA13: 21000 | BB13: 21000 | BC13: 21000 | BD13: 21000 | BE13: 21000 | BF13: 21000 | BG13: 21000 | BH13: 21000 | BI13: 21000 | BJ13: 21000 | BK13: 21000 | BL13: 21000 | BM13: 21000 | BN13: 21000 | BO13: 21000 | BP13: 21000 | BQ13: 21000 | BR13: 21000 | BS13: 21000 | BT13: 21000 | BU13: 21000 | BV13: 21000 | BW13: 21000 | BX13: 21000 | BY13: 21000 | BZ13: 21000 | CA13: 21000 | CB13: 21000 | CC13: 21000 | CD13: 21000 | CE13: 21000 | CF13: 21000 | CG13: 21000 | CH13: 21000 | CI13: 21000 | CJ13: 21000 | CK13: 21000 | CL13: 21000 | CM13: 21000 | CN13: 21000 | CO13: 21000 | CP13: 21000 | CQ13: 21000 | CR13: 21000 | CS13: 21000 | CT13: 21000 | CU13: 21000 | CV13: 21000 | CW13: 21000 | CX13: 21000 | CY13: 21000 | CZ13: 21000 | DA13: 21000 | DB13: 21000 | DC13: 21000 | DD13: 21000 | DE13: 21000 | DF13: 21000 | DG13: 21000 | DH13: 21000
A14: 9 | B14: ሲንታየሁ ካሳ | C14: 21000 | D14: =Sheet3!C10 -> 108 | E14: 21000 | F14: 21000 | G14: 21000 | H14: 21000 | I14: 21000 | J14: 21000 | K14: 21000 | L14: 21000 | M14: 21000 | N14: 21000 | O14: 21000 | P14: 21000 | Q14: 21000 | R14: 21000 | S14: 21000 | T14: 21000 | U14: 21000 | V14: 21000 | W14: 21000 | X14: 21000 | Y14: 21000 | Z14: 21000 | AA14: 21000 | AB14: 21000 | AC14: 21000 | AD14: 21000 | AE14: 21000 | AF14: 21000 | AG14: 21000 | AH14: 21000 | AI14: 21000 | AJ14: 21000 | AK14: 21000 | AL14: 21000 | AM14: 21000 | AN14: 21000 | AO14: 21000 | AP14: 21000 | AQ14: 21000 | AR14: 21000 | AS14: 21000 | AT14: 21000 | AU14: 21000 | AV14: 21000 | AW14: 21000 | AX14: 21000 | AY14: 21000 | AZ14: 21000 | BA14: 21000 | BB14: 21000 | BC14: 21000 | BD14: 21000 | BE14: 21000 | BF14: 21000 | BG14: 21000 | BH14: 21000 | BI14: 21000 | BJ14: 21000 | BK14: 21000 | BL14: 21000 | BM14: 21000 | BN14: 21000 | BO14: 21000 | BP14: 0 | BQ14: 42000 | BR14: 21000 | BS14: 21000 | BT14: 21000 | BU14: 21000 | BV14: 21000 | BW14: 21000 | BX14: 21000 | BY14: 21000 | BZ14: 21000 | CA14: 21000 | CB14: 21000 | CC14: 21000 | CD14: 21000 | CE14: 21000 | CF14: 21000 | CG14: 21000 | CH14: 21000 | CI14: 21000 | CJ14: 21000 | CK14: 21000 | CL14: 21000 | CM14: 21000 | CN14: 21000 | CO14: 21000 | CP14: 21000 | CQ14: 21000 | CR14: 21000 | CS14: 21000 | CT14: 21000 | CU14: 21000 | CV14: 21000 | CW14: 21000 | CX14: 21000 | CY14: 21000 | CZ14: 21000 | DA14: 21000 | DB14: 21000 | DC14: 21000 | DD14: 21000 | DE14: 21000 | DF14: 21000 | DG14: 21000 | DH14: 21000
A15: 10 | B15: ጥላነሽ ከበደ | C15: 21000 | D15: =Sheet3!C11 -> 108 | E15: 21000 | F15: 21000 | G15: 21000 | H15: 21000 | I15: 21000 | J15: 21000 | K15: 21000 | L15: 21000 | M15: 21000 | N15: 21000 | O15: 21000 | P15: 21000 | Q15: 21000 | R15: 21000 | S15: 21000 | T15: 21000 | U15: 21000 | V15: 21000 | W15: 21000 | X15: 21000 | Y15: 21000 | Z15: 21000 | AA15: 21000 | AB15: 21000 | AC15: 21000 | AD15: 21000 | AE15: 21000 | AF15: 21000 | AG15: 21000 | AH15: 21000 | AI15: 21000 | AJ15: 21000 | AK15: 21000 | AL15: 21000 | AM15: 21000 | AN15: 21000 | AO15: 21000 | AP15: 0 | AQ15: 42000 | AR15: 21000 | AS15: 21000 | AT15: 21000 | AU15: 21000 | AV15: 21000 | AW15: 21000 | AX15: 21000 | AY15: 21000 | AZ15: 21000 | BA15: 21000 | BB15: 21000 | BC15: 21000 | BD15: 21000 | BE15: 21000 | BF15: 21000 | BG15: 21000 | BH15: 21000 | BI15: 21000 | BJ15: 21000 | BK15: 21000 | BL15: 21000 | BM15: 21000 | BN15: 0 | BO15: 42000 | BP15: 21000 | BQ15: 21000 | BR15: 21000 | BS15: 21000 | BT15: 21000 | BU15: 21000 | BV15: 21000 | BW15: 21000 | BX15: 21000 | BY15: 21000 | BZ15: 21000 | CA15: 21000 | CB15: 21000 | CC15: 21000 | CD15: 21000 | CE15: 0 | CF15: 42000 | CG15: 21000 | CH15: 21000 | CI15: 21000 | CJ15: 21000 | CK15: 21000 | CL15: 21000 | CM15: 21000 | CN15: 21000 | CO15: 21000 | CP15: 21000 | CQ15: 21000 | CR15: 21000 | CS15: 21000 | CT15: 21000 | CU15: 21000 | CV15: 21000 | CW15: 21000 | CX15: 21000 | CY15: 21000 | CZ15: 21000 | DA15: 21000 | DB15: 21000 | DC15: 21000 | DD15: 21000 | DE15: 21000 | DF15: 21000 | DG15: 21000 | DH15: 21000
A16: 11 | B16: ሄኖክ በቀለ | C16: 21000 | D16: =Sheet3!C12 -> 101 | E16: 21000 | F16: 21000 | G16: 21000 | H16: 21000 | I16: 21000 | J16: 21000 | K16: 21000 | L16: 21000 | M16: 21000 | N16: 21000 | O16: 21000 | P16: 21000 | Q16: 21000 | R16: 21000 | S16: 21000 | T16: 21000 | U16: 21000 | V16: 21000 | W16: 21000 | X16: 21000 | Y16: 21000 | Z16: 21000 | AA16: 21000 | AB16: 21000 | AC16: 21000 | AD16: 21000 | AE16: 21000 | AF16: 21000 | AG16: 0 | AH16: 42000 | AI16: 21000 | AJ16: 21000 | AK16: 21000 | AL16: 21000 | AM16: 21000 | AN16: 21000 | AO16: 21000 | AP16: 21000 | AQ16: 21000 | AR16: 21000 | AS16: 21000 | AT16: 21000 | AU16: 21000 | AV16: 0 | AW16: 42000 | AX16: 21000 | AY16: 21000 | AZ16: 21000 | BA16: 21000 | BB16: 21000 | BC16: 21000 | BD16: 0 | BE16: 21000 | BF16: 21000 | BG16: 21000 | BH16: 42000 | BI16: 21000 | BJ16: 21000 | BK16: 21000 | BL16: 21000 | BM16: 21000 | BN16: 0 | BO16: 21000 | BP16: 21000 | BQ16: 21000 | BR16: 21000 | BS16: 21000 | BT16: 21000 | BU16: 21000 | BV16: 21000 | BW16: 21000 | BX16: 0 | BY16: 21000 | BZ16: 0 | CA16: 0 | CB16: 0 | CC16: 0 | CD16: 0 | CE16: 0 | CF16: 21000 | CG16: 21000 | CH16: 21000 | CI16: 21000 | CJ16: 42000 | CK16: 0 | CL16: 0 | CM16: 21000 | CN16: 21000 | CO16: 0 | CP16: 0 | CQ16: 0 | CR16: 21000 | CS16: 0 | CT16: 84000 | CU16: 0 | CV16: 63000 | CW16: 0 | CX16: 63000 | CY16: 21000 | CZ16: 42000 | DA16: 21000 | DB16: 21000 | DC16: 0 | DD16: 21000 | DE16: 42000 | DF16: 0 | DG16: 42000 | DH16: 21000
A17: 12 | B17: ሀብታሙ ፃዲቁ | C17: 21000 | D17: =Sheet3!C13 -> 0 | E17: 0 | F17: 0 | G17: 0 | H17: 0 | I17: 0 | J17: 0 | K17: 0 | L17: 0 | M17: 0 | N17: 0 | O17: 0 | P17: 0 | Q17: 0 | R17: 0 | S17: 0 | T17: 0 | U17: 0 | V17: 0 | W17: 0 | X17: 0 | Y17: 0 | Z17: 0 | AA17: 0 | AB17: 0 | AC17: 0 | AD17: 0 | AE17: 0 | AF17: 0 | AG17: 0 | AH17: 0 | AI17: 0 | AJ17: 0 | AK17: 0 | AL17: 0 | AM17: 0 | AN17: 0 | AO17: 0 | AP17: 0 | AQ17: 0 | AR17: 0 | AS17: 0 | AT17: 0 | AU17: 0 | AV17: 0 | AW17: 0 | AX17: 0 | AY17: 0 | AZ17: 0 | BA17: 0 | BB17: 0 | BC17: 0 | BD17: 0 | BE17: 0 | BF17: 0 | BG17: 0 | BH17: 0 | BI17: 0 | BJ17: 0 | BK17: 0 | BL17: 0 | BM17: 0 | BN17: 0 | BO17: 0 | BP17: 0 | BQ17: 0 | BR17: 0 | BS17: 0 | BT17: 0 | BV17: 0 | BW17: 0 | BX17: 0 | BY17: 0 | BZ17: 0 | CA17: 0 | CB17: 0 | CC17: 0 | CD17: 0 | CE17: 0 | CF17: 0 | CG17: 0 | CH17: 0 | CI17: 0 | CJ17: 0 | CK17: 0 | CL17: 0 | CM17: 0 | CN17: 0 | CO17: 0 | CP17: 0 | CQ17: 0 | CR17: 0 | CS17: 0 | CT17: 0 | CU17: 0 | CV17: 0 | CW17: 0 | CX17: 0 | CY17: 0 | CZ17: 0 | DA17: 0 | DB17: 0 | DC17: 0 | DD17: 0 | DE17: 0 | DF17: 0
A18: 13 | B18: ፍሬው ኢትዮጲያ | C18: 21000 | D18: =Sheet3!C14 -> 108 | E18: 21000 | F18: 21000 | G18: 21000 | H18: 21000 | I18: 21000 | J18: 21000 | K18: 21000 | L18: 21000 | M18: 21000 | N18: 21000 | O18: 21000 | P18: 21000 | Q18: 21000 | R18: 21000 | S18: 21000 | T18: 21000 | U18: 21000 | V18: 21000 | W18: 21000 | X18: 21000 | Y18: 21000 | Z18: 21000 | AA18: 21000 | AB18: 21000 | AC18: 21000 | AD18: 21000 | AE18: 21000 | AF18: 21000 | AG18: 21000 | AH18: 21000 | AI18: 21000 | AJ18: 21000 | AK18: 21000 | AL18: 21000 | AM18: 21000 | AN18: 21000 | AO18: 21000 | AP18: 21000 | AQ18: 21000 | AR18: 21000 | AS18: 21000 | AT18: 21000 | AU18: 21000 | AV18: 21000 | AW18: 21000 | AX18: 21000 | AY18: 21000 | AZ18: 21000 | BA18: 21000 | BB18: 21000 | BC18: 21000 | BD18: 21000 | BE18: 21000 | BF18: 21000 | BG18: 21000 | BH18: 21000 | BI18: 21000 | BJ18: 21000 | BK18: 21000 | BL18: 21000 | BM18: 21000 | BN18: 21000 | BO18: 21000 | BP18: 21000 | BQ18: 21000 | BR18: 21000 | BS18: 21000 | BT18: 21000 | BU18: 21000 | BV18: 21000 | BW18: 21000 | BX18: 21000 | BY18: 21000 | BZ18: 21000 | CA18: 21000 | CB18: 21000 | CC18: 21000 | CD18: 21000 | CE18: 21000 | CF18: 21000 | CG18: 21000 | CH18: 21000 | CI18: 21000 | CJ18: 21000 | CK18: 21000 | CL18: 21000 | CM18: 21000 | CN18: 21000 | CO18: 21000 | CP18: 21000 | CQ18: 21000 | CR18: 21000 | CS18: 21000 | CT18: 21000 | CU18: 21000 | CV18: 21000 | CW18: 21000 | CX18: 21000 | CY18: 21000 | CZ18: 21000 | DA18: 21000 | DB18: 21000 | DC18: 21000 | DD18: 21000 | DE18: 21000 | DF18: 21000 | DG18: 21000 | DH18: 21000
A19: 14 | B19: አስራት ኩሳ | C19: 21000 | D19: =Sheet3!C15 -> 106 | E19: 21000 | F19: 21000 | G19: 21000 | H19: 21000 | I19: 21000 | J19: 21000 | K19: 21000 | L19: 21000 | M19: 21000 | N19: 21000 | O19: 21000 | P19: 21000 | Q19: 21000 | R19: 21000 | S19: 21000 | T19: 21000 | U19: 21000 | V19: 21000 | W19: 21000 | X19: 0 | Y19: 42000 | Z19: 21000 | AA19: 21000 | AB19: 21000 | AC19: 21000 | AD19: 21000 | AE19: 21000 | AF19: 0 | AG19: 42000 | AH19: 21000 | AI19: 21000 | AJ19: 0 | AK19: 42000 | AL19: 21000 | AM19: 21000 | AN19: 0 | AO19: 42000 | AP19: 21000 | AQ19: 21000 | AR19: 21000 | AS19: 21000 | AT19: 21000 | AU19: 21000 | AV19: 21000 | AW19: 0 | AX19: 21000 | AY19: 21000 | AZ19: 42000 | BA19: 21000 | BB19: 21000 | BC19: 21000 | BD19: 21000 | BE19: 21000 | BF19: 21000 | BG19: 21000 | BH19: 0 | BI19: 42000 | BJ19: 21000 | BK19: 21000 | BL19: 0 | BM19: 42000 | BN19: 21000 | BO19: 21000 | BP19: 0 | BQ19: 42000 | BS19: 21000 | BT19: 21000 | BU19: 42000 | BV19: 21000 | BW19: 21000 | BX19: 0 | BY19: 42000 | BZ19: 0 | CA19: 42000 | CB19: 21000 | CC19: 21000 | CD19: 21000 | CE19: 0 | CF19: 42000 | CG19: 0 | CH19: 21000 | CI19: 42000 | CJ19: 21000 | CK19: 21000 | CL19: 21000 | CM19: 0 | CN19: 42000 | CO19: 21000 | CP19: 0 | CQ19: 42000 | CR19: 0 | CS19: 42000 | CT19: 0 | CU19: 0 | CV19: 0 | CW19: 63000 | CX19: 0 | CY19: 0 | CZ19: 0 | DA19: 105000 | DB19: 21000 | DC19: 0 | DD19: 0 | DE19: 42000 | DF19: 0 | DG19: 42000
A20: 15 | B20: አበራ ዩሐንስ | C20: 21000 | D20: =Sheet3!C16 -> 88 | E20: 21000 | F20: 21000 | G20: 21000 | H20: 21000 | I20: 21000 | J20: 21000 | K20: 21000 | L20: 21000 | M20: 21000 | N20: 21000 | O20: 21000 | P20: 21000 | Q20: 21000 | R20: 21000 | S20: 21000 | T20: 21000 | U20: 21000 | V20: 21000 | W20: 21000 | X20: 21000 | Y20: 21000 | Z20: 21000 | AA20: 21000 | AB20: 21000 | AC20: 21000 | AD20: 21000 | AE20: 21000 | AF20: 21000 | AG20: 21000 | AH20: 21000 | AI20: 21000 | AJ20: 21000 | AK20: 21000 | AL20: 21000 | AM20: 21000 | AN20: 21000 | AO20: 21000 | AP20: 21000 | AQ20: 21000 | AR20: 21000 | AS20: 21000 | AT20: 21000 | AU20: 21000 | AV20: 0 | AW20: 0 | AX20: 0 | AY20: 21000 | AZ20: 21000 | BA20: 63000 | BB20: 21000 | BC20: 42000 | BD20: 21000 | BE20: 21000 | BF20: 21000 | BG20: 21000 | BH20: 21000 | BI20: 21000 | BJ20: 21000 | BK20: 21000 | BL20: 21000 | BM20: 0 | BN20: 0 | BO20: 0 | BP20: 21000 | BQ20: 0 | BR20: 0 | BS20: 42000 | BT20: 21000 | BU20: 21000 | BV20: 0 | BW20: 0 | BX20: 0 | BY20: 0 | BZ20: 0 | CA20: 0 | CB20: 0 | CC20: 0 | CD20: 21000 | CE20: 0 | CF20: 0 | CG20: 0 | CH20: 0 | CI20: 0 | CJ20: 0 | CK20: 0 | CL20: 0 | CM20: 0 | CN20: 0 | CO20: 0 | CP20: 252000 | CQ20: 105000 | CR20: 105000 | CS20: 0 | CT20: 0 | CU20: 0 | CV20: 0 | CW20: 0 | CX20: 0 | CY20: 0 | CZ20: 0 | DA20: 0 | DB20: 0 | DC20: 0 | DD20: 0 | DE20: 0 | DF20: 0
A21: 16 | B21: አለማየሁ ገዛህኝ | C21: 21000 | D21: =Sheet3!C17 -> 108 | E21: 21000 | F21: 21000 | G21: 21000 | H21: 21000 | I21: 21000 | J21: 21000 | K21: 21000 | L21: 21000 | M21: 21000 | N21: 21000 | O21: 21000 | P21: 21000 | Q21: 21000 | R21: 21000 | S21: 21000 | T21: 21000 | U21: 21000 | V21: 21000 | W21: 21000 | X21: 21000 | Y21: 21000 | Z21: 21000 | AA21: 21000 | AB21: 21000 | AC21: 21000 | AD21: 21000 | AE21: 21000 | AF21: 21000 | AG21: 21000 | AH21: 21000 | AI21: 21000 | AJ21: 21000 | AK21: 21000 | AL21: 21000 | AM21: 21000 | AN21: 21000 | AO21: 21000 | AP21: 21000 | AQ21: 21000 | AR21: 21000 | AS21: 21000 | AT21: 21000 | AU21: 21000 | AV21: 21000 | AW21: 21000 | AX21: 21000 | AY21: 21000 | AZ21: 21000 | BA21: 21000 | BB21: 21000 | BC21: 21000 | BD21: 0 | BE21: 42000 | BF21: 21000 | BG21: 21000 | BH21: 21000 | BI21: 21000 | BJ21: 21000 | BK21: 21000 | BL21: 21000 | BM21: 21000 | BN21: 21000 | BO21: 21000 | BP21: 21000 | BQ21: 21000 | BR21: 21000 | BS21: 21000 | BT21: 21000 | BU21: 21000 | BV21: 21000 | BW21: 21000 | BX21: 21000 | BY21: 21000 | BZ21: 21000 | CA21: 21000 | CB21: 21000 | CC21: 21000 | CD21: 21000 | CE21: 21000 | CF21: 21000 | CG21: 21000 | CH21: 21000 | CI21: 21000 | CJ21: 21000 | CK21: 21000 | CL21: 21000 | CM21: 21000 | CN21: 21000 | CO21: 21000 | CP21: 0 | CQ21: 42000 | CR21: 21000 | CS21: 21000 | CT21: 21000 | CU21: 21000 | CV21: 21000 | CW21: 21000 | CX21: 21000 | CY21: 21000 | CZ21: 21000 | DA21: 21000 | DB21: 21000 | DC21: 21000 | DD21: 21000 | DE21: 21000 | DF21: 21000 | DG21: 21000 | DH21: 21000
A22: 17 | B22: እንግዳ ካሳዬ | C22: 21000 | D22: =Sheet3!C18 -> 100 | E22: 21000 | F22: 21000 | G22: 21000 | H22: 21000 | I22: 21000 | J22: 21000 | K22: 21000 | L22: 21000 | M22: 21000 | N22: 21000 | O22: 21000 | P22: 21000 | Q22: 21000 | R22: 21000 | S22: 21000 | T22: 21000 | U22: 21000 | V22: 21000 | W22: 21000 | X22: 21000 | Y22: 21000 | Z22: 21000 | AA22: 21000 | AB22: 0 | AC22: 42000 | AD22: 21000 | AE22: 21000 | AF22: 21000 | AG22: 21000 | AH22: 21000 | AI22: 21000 | AJ22: 21000 | AK22: 21000 | AL22: 21000 | AM22: 21000 | AN22: 21000 | AO22: 21000 | AP22: 21000 | AQ22: 21000 | AR22: 21000 | AS22: 21000 | AT22: 21000 | AU22: 21000 | AV22: 21000 | AW22: 21000 | AX22: 21000 | AY22: 21000 | AZ22: 21000 | BA22: 21000 | BB22: 21000 | BC22: 21000 | BD22: 21000 | BE22: 21000 | BF22: 0 | BG22: 21000 | BH22: 21000 | BI22: 21000 | BJ22: 21000 | BK22: 21000 | BL22: 21000 | BM22: 21000 | BN22: 0 | BO22: 42000 | BP22: 21000 | BQ22: 21000 | BR22: 21000 | BS22: 21000 | BT22: 21000 | BU22: 21000 | BV22: 21000 | BW22: 21000 | BX22: 21000 | BY22: 21000 | BZ22: 21000 | CA22: 21000 | CB22: 0 | CC22: 42000 | CD22: 21000 | CE22: 0 | CF22: 21000 | CG22: 0 | CH22: 21000 | CI22: 21000 | CJ22: 21000 | CK22: 21000 | CL22: 0 | CM22: 42000 | CN22: 21000 | CO22: 21000 | CP22: 0 | CQ22: 21000 | CR22: 21000 | CS22: 21000 | CT22: 21000 | CU22: 21000 | CV22: 21000 | CW22: 0 | CX22: 21000 | CY22: 0 | CZ22: 0 | DA22: 21000 | DB22: 21000 | DC22: 21000 | DD22: 0 | DE22: 21000 | DF22: 21000 | DG22: 21000 | DH22: 21000
A23: 18 | B23: ህዝቄል ጴጥሮስ | C23: 21000 | D23: =Sheet3!C19 -> 106 | E23: 21000 | F23: 21000 | G23: 21000 | H23: 21000 | I23: 21000 | J23: 21000 | K23: 21000 | L23: 21000 | M23: 21000 | N23: 21000 | O23: 21000 | P23: 21000 | Q23: 21000 | R23: 21000 | S23: 21000 | T23: 21000 | U23: 21000 | V23: 21000 | W23: 21000 | X23: 21000 | Y23: 21000 | Z23: 21000 | AA23: 21000 | AB23: 21000 | AC23: 21000 | AD23: 21000 | AE23: 21000 | AF23: 21000 | AG23: 21000 | AH23: 21000 | AI23: 21000 | AJ23: 21000 | AK23: 21000 | AL23: 0 | AM23: 42000 | AN23: 21000 | AO23: 21000 | AP23: 21000 | AQ23: 21000 | AR23: 21000 | AS23: 21000 | AT23: 21000 | AU23: 21000 | AV23: 21000 | AW23: 21000 | AX23: 21000 | AY23: 21000 | AZ23: 21000 | BA23: 21000 | BB23: 21000 | BC23: 21000 | BD23: 21000 | BE23: 21000 | BF23: 21000 | BG23: 21000 | BH23: 21000 | BI23: 21000 | BJ23: 21000 | BK23: 21000 | BL23: 21000 | BM23: 21000 | BN23: 21000 | BO23: 21000 | BP23: 21000 | BR23: 21000 | BS23: 21000 | BT23: 21000 | BU23: 21000 | BV23: 21000 | BW23: 21000 | BX23: 21000 | BY23: 21000 | BZ23: 21000 | CA23: 21000 | CB23: 21000 | CC23: 21000 | CD23: 21000 | CE23: 0 | CF23: 42000 | CG23: 21000 | CH23: 21000 | CI23: 21000 | CJ23: 21000 | CK23: 21000 | CL23: 0 | CM23: 42000 | CN23: 21000 | CO23: 21000 | CP23: 21000 | CQ23: 21000 | CR23: 21000 | CS23: 0 | CT23: 21000 | CU23: 21000 | CV23: 21000 | CW23: 21000 | CX23: 21000 | CY23: 21000 | CZ23: 21000 | DA23: 21000 | DB23: 21000 | DC23: 0 | DD23: 42000 | DE23: 0 | DF23: 42000 | DH23: 42000
A24: 19 | B24: አንተነህ ግዛዉ | C24: 10500 | D24: =Sheet3!C20 -> 105 | E24: 10500 | F24: 10500 | G24: 10500 | H24: 10500 | I24: 10500 | J24: 10500 | K24: 10500 | L24: 10500 | M24: 10500 | N24: 10500 | O24: 10500 | P24: 10500 | Q24: 10500 | R24: 10500 | S24: 10500 | T24: 10500 | U24: 10500 | V24: 10500 | W24: 10500 | X24: 10500 | Y24: 10500 | Z24: 0 | AA24: 21000 | AB24: 10500 | AC24: 10500 | AD24: 10500 | AE24: 0 | AF24: 10500 | AG24: 21000 | AH24: 10500 | AI24: 10500 | AJ24: 0 | AK24: 21000 | AL24: 10500 | AM24: 10500 | AN24: 10500 | AO24: 10500 | AP24: 10500 | AQ24: 0 | AR24: 10500 | AS24: 21000 | AT24: 0 | AU24: 21000 | AV24: 10500 | AW24: 10500 | AX24: 10500 | AY24: 10500 | AZ24: 0 | BA24: 10500 | BB24: 10500 | BC24: 10500 | BD24: 10500 | BE24: 10500 | BF24: 10500 | BG24: 10500 | BH24: 10500 | BI24: 10500 | BJ24: 10500 | BK24: 10500 | BL24: 10500 | BM24: 10500 | BN24: 10500 | BO24: 10500 | BP24: 0 | BQ24: 21000 | BR24: 10500 | BS24: 10500 | BU24: 21000 | BV24: 0 | BW24: 21000 | BX24: 10500 | BY24: 10500 | BZ24: 10500 | CA24: 10500 | CB24: 10500 | CC24: 10500 | CD24: 10500 | CE24: 0 | CF24: 10500 | CG24: 10500 | CH24: 10500 | CI24: 0 | CJ24: 21000 | CK24: 10500 | CL24: 10500 | CM24: 10500 | CN24: 10500 | CO24: 10500 | CP24: 10500 | CQ24: 10500 | CR24: 10500 | CS24: 10500 | CT24: 10500 | CU24: 10500 | CV24: 10500 | CW24: 10500 | CX24: 0 | CY24: 21000 | CZ24: 0 | DA24: 21000 | DB24: 10500 | DC24: 0 | DD24: 0 | DE24: 21000 | DF24: 10500 | DG24: 10500 | DH24: 10500
A25: 19 | B25: አለማየሁ ገዛህኝ | C25: 10500 | D25: =Sheet3!C21 -> 108 | E25: 10500 | F25: 10500 | G25: 10500 | H25: 10500 | I25: 10500 | J25: 10500 | K25: 10500 | L25: 10500 | M25: 10500 | N25: 10500 | O25: 10500 | P25: 10500 | Q25: 10500 | R25: 10500 | S25: 10500 | T25: 10500 | U25: 10500 | V25: 10500 | W25: 10500 | X25: 10500 | Y25: 10500 | Z25: 10500 | AA25: 10500 | AB25: 10500 | AC25: 10500 | AD25: 10500 | AE25: 10500 | AF25: 10500 | AG25: 10500 | AH25: 10500 | AI25: 10500 | AJ25: 10500 | AK25: 10500 | AL25: 10500 | AM25: 10500 | AN25: 10500 | AO25: 10500 | AP25: 10500 | AQ25: 10500 | AR25: 10500 | AS25: 10500 | AT25: 10500 | AU25: 10500 | AV25: 10500 | AW25: 10500 | AX25: 10500 | AY25: 10500 | AZ25: 10500 | BA25: 10500 | BB25: 10500 | BC25: 10500 | BD25: 0 | BE25: 21000 | BF25: 10500 | BG25: 10500 | BH25: 10500 | BI25: 10500 | BJ25: 10500 | BK25: 10500 | BL25: 10500 | BM25: 10500 | BN25: 10500 | BO25: 10500 | BP25: 10500 | BQ25: 10500 | BR25: 10500 | BS25: 10500 | BT25: 10500 | BU25: 10500 | BV25: 10500 | BW25: 10500 | BX25: 10500 | BY25: 10500 | BZ25: 10500 | CA25: 10500 | CB25: 10500 | CC25: 10500 | CD25: 10500 | CE25: 10500 | CF25: 10500 | CG25: 10500 | CH25: 10500 | CI25: 10500 | CJ25: 10500 | CK25: 10500 | CL25: 10500 | CM25: 10500 | CN25: 10500 | CO25: 10500 | CP25: 0 | CQ25: 10500 | CR25: 10500 | CS25: 10500 | CT25: 21000 | CU25: 10500 | CV25: 10500 | CW25: 10500 | CX25: 10500 | CY25: 10500 | CZ25: 10500 | DA25: 10500 | DB25: 10500 | DC25: 10500 | DD25: 10500 | DE25: 10500 | DF25: 10500 | DG25: 10500 | DH25: 10500
A26: 20 | B26: ሻምበል ቦንጃ | C26: 21000 | D26: =Sheet3!C22 -> 106 | E26: 21000 | F26: 21000 | G26: 21000 | H26: 21000 | I26: 21000 | J26: 21000 | K26: 21000 | L26: 21000 | M26: 21000 | N26: 21000 | O26: 21000 | P26: 21000 | Q26: 21000 | R26: 21000 | S26: 21000 | T26: 21000 | U26: 21000 | V26: 21000 | W26: 21000 | X26: 21000 | Y26: 21000 | Z26: 21000 | AA26: 21000 | AB26: 21000 | AC26: 21000 | AD26: 21000 | AE26: 21000 | AF26: 0 | AG26: 42000 | AH26: 21000 | AI26: 21000 | AJ26: 21000 | AK26: 21000 | AL26: 21000 | AM26: 0 | AN26: 42000 | AO26: 21000 | AP26: 21000 | AQ26: 21000 | AR26: 21000 | AS26: 0 | AT26: 42000 | AU26: 0 | AV26: 42000 | AW26: 21000 | AX26: 21000 | AY26: 0 | AZ26: 42000 | BA26: 0 | BB26: 42000 | BC26: 21000 | BD26: 0 | BE26: 42000 | BF26: 0 | BG26: 42000 | BH26: 21000 | BI26: 21000 | BJ26: 21000 | BK26: 21000 | BL26: 21000 | BM26: 21000 | BN26: 0 | BO26: 42000 | BP26: 21000 | BQ26: 21000 | BS26: 42000 | BT26: 21000 | BV26: 0 | BW26: 63000 | BX26: 0 | BY26: 42000 | BZ26: 0 | CA26: 0 | CB26: 63000 | CC26: 21000 | CD26: 21000 | CE26: 0 | CF26: 0 | CG26: 63000 | CH26: 21000 | CI26: 21000 | CJ26: 21000 | CK26: 0 | CL26: 0 | CM26: 42000 | CN26: 0 | CO26: 0 | CP26: 42000 | CQ26: 0 | CR26: 42000 | CS26: 21000 | CT26: 0 | CU26: 42000 | CV26: 0 | CW26: 42000 | CX26: 0 | CY26: 42000 | CZ26: 0 | DA26: 42000 | DB26: 21000 | DC26: 0 | DD26: 42000 | DE26: 0 | DF26: 42000 | DH26: 42000
A27: 21 | B27: ማተጎ አመኖ | C27: 21000 | D27: =Sheet3!C23 -> 106 | E27: 21000 | F27: 21000 | G27: 21000 | H27: 21000 | I27: 21000 | J27: 21000 | K27: 21000 | L27: 21000 | M27: 21000 | N27: 21000 | O27: 21000 | P27: 21000 | Q27: 21000 | R27: 21000 | S27: 21000 | T27: 21000 | U27: 21000 | V27: 21000 | W27: 21000 | X27: 0 | Y27: 42000 | Z27: 21000 | AA27: 21000 | AB27: 0 | AC27: 42000 | AD27: 21000 | AE27: 21000 | AF27: 0 | AG27: 42000 | AH27: 21000 | AI27: 21000 | AJ27: 0 | AK27: 42000 | AL27: 21000 | AM27: 21000 | AN27: 21000 | AO27: 21000 | AP27: 21000 | AQ27: 21000 | AR27: 21000 | AS27: 21000 | AT27: 21000 | AU27: 21000 | AV27: 21000 | AW27: 21000 | AX27: 21000 | AY27: 21000 | AZ27: 0 | BA27: 42000 | BB27: 21000 | BC27: 21000 | BD27: 0 | BE27: 42000 | BF27: 21000 | BG27: 21000 | BH27: 0 | BI27: 42000 | BJ27: 21000 | BK27: 21000 | BL27: 0 | BM27: 42000 | BN27: 21000 | BO27: 21000 | BP27: 0 | BQ27: 42000 | BR27: 21000 | BS27: 21000 | BU27: 21000 | BV27: 21000 | BW27: 42000 | BX27: 21000 | BY27: 21000 | BZ27: 21000 | CA27: 21000 | CB27: 21000 | CC27: 21000 | CD27: 21000 | CE27: 0 | CF27: 21000 | CG27: 21000 | CH27: 21000 | CI27: 21000 | CJ27: 21000 | CK27: 21000 | CL27: 21000 | CM27: 21000 | CN27: 21000 | CO27: 21000 | CP27: 21000 | CQ27: 42000 | CR27: 0 | CS27: 21000 | CT27: 21000 | CU27: 21000 | CV27: 21000 | CW27: 21000 | CX27: 21000 | CY27: 21000 | CZ27: 0 | DA27: 21000 | DB27: 21000 | DC27: 21000 | DD27: 0 | DE27: 42000 | DF27: 21000 | DG27: 21000 | DH27: 21000
A28: 22 | B28: ማሩ እርቅይሁን | C28: 21000 | D28: =Sheet3!C24 -> 108 | E28: 21000 | F28: 21000 | G28: 21000 | H28: 21000 | I28: 21000 | J28: 21000 | K28: 21000 | L28: 21000 | M28: 21000 | N28: 21000 | O28: 21000 | P28: 21000 | Q28: 21000 | R28: 21000 | S28: 21000 | T28: 21000 | U28: 21000 | V28: 21000 | W28: 21000 | X28: 21000 | Y28: 21000 | Z28: 21000 | AA28: 21000 | AB28: 21000 | AC28: 21000 | AD28: 21000 | AE28: 21000 | AF28: 21000 | AG28: 21000 | AH28: 21000 | AI28: 21000 | AJ28: 21000 | AK28: 21000 | AL28: 21000 | AM28: 21000 | AN28: 21000 | AO28: 21000 | AP28: 0 | AQ28: 42000 | AR28: 21000 | AS28: 21000 | AT28: 21000 | AU28: 21000 | AV28: 21000 | AW28: 21000 | AX28: 21000 | AY28: 21000 | AZ28: 21000 | BA28: 21000 | BB28: 21000 | BC28: 21000 | BD28: 21000 | BE28: 21000 | BF28: 21000 | BG28: 21000 | BH28: 21000 | BI28: 21000 | BJ28: 21000 | BK28: 21000 | BL28: 21000 | BM28: 21000 | BN28: 0 | BO28: 42000 | BP28: 21000 | BQ28: 21000 | BR28: 21000 | BS28: 21000 | BT28: 21000 | BU28: 21000 | BV28: 21000 | BW28: 21000 | BX28: 21000 | BY28: 21000 | BZ28: 21000 | CA28: 21000 | CB28: 21000 | CC28: 21000 | CD28: 21000 | CE28: 0 | CF28: 42000 | CG28: 21000 | CH28: 21000 | CI28: 21000 | CJ28: 21000 | CK28: 21000 | CL28: 21000 | CM28: 21000 | CN28: 21000 | CO28: 21000 | CP28: 21000 | CQ28: 21000 | CR28: 21000 | CS28: 21000 | CT28: 21000 | CU28: 21000 | CV28: 21000 | CW28: 21000 | CX28: 21000 | CY28: 21000 | CZ28: 21000 | DA28: 21000 | DB28: 21000 | DC28: 21000 | DD28: 21000 | DE28: 21000 | DF28: 21000 | DG28: 21000 | DH28: 21000
A29: 23 | B29: ደረጀ ታደግ | C29: 21000 | D29: =Sheet3!C25 -> 103 | E29: 21000 | F29: 21000 | G29: 21000 | H29: 21000 | I29: 21000 | J29: 21000 | K29: 21000 | L29: 21000 | M29: 21000 | N29: 21000 | O29: 21000 | P29: 21000 | Q29: 21000 | R29: 21000 | S29: 21000 | T29: 21000 | U29: 21000 | V29: 21000 | W29: 21000 | X29: 21000 | Y29: 21000 | Z29: 21000 | AA29: 21000 | AB29: 21000 | AC29: 21000 | AD29: 21000 | AE29: 21000 | AF29: 0 | AG29: 42000 | AH29: 21000 | AI29: 21000 | AJ29: 21000 | AK29: 21000 | AL29: 21000 | AM29: 21000 | AN29: 21000 | AO29: 21000 | AP29: 21000 | AQ29: 21000 | AR29: 21000 | AS29: 21000 | AT29: 21000 | AU29: 21000 | AV29: 21000 | AW29: 21000 | AX29: 21000 | AY29: 21000 | AZ29: 0 | BA29: 42000 | BB29: 21000 | BC29: 21000 | BD29: 21000 | BE29: 21000 | BF29: 21000 | BG29: 21000 | BH29: 21000 | BI29: 21000 | BJ29: 21000 | BK29: 21000 | BL29: 21000 | BM29: 21000 | BN29: 21000 | BO29: 21000 | BP29: 21000 | BQ29: 21000 | BR29: 21000 | BS29: 21000 | BU29: 42000 | BV29: 21000 | BW29: 21000 | BX29: 0 | BY29: 21000 | BZ29: 21000 | CA29: 21000 | CB29: 21000 | CC29: 21000 | CD29: 21000 | CE29: 21000 | CF29: 21000 | CG29: 21000 | CH29: 21000 | CI29: 21000 | CJ29: 21000 | CK29: 0 | CL29: 42000 | CM29: 21000 | CN29: 21000 | CO29: 0 | CP29: 0 | CQ29: 63000 | CR29: 21000 | CS29: 0 | CT29: 21000 | CU29: 21000 | CV29: 21000 | CW29: 21000 | CX29: 21000 | CY29: 21000 | CZ29: 21000 | DA29: 0 | DB29: 0 | DC29: 21000 | DD29: 0 | DE29: 21000 | DF29: 21000 | DG29: 21000 | DH29: 21000
A30: 24 | B30: ስንቅነሽ ጃራ | C30: 21000 | D30: =Sheet3!C26 -> 108 | E30: 21000 | F30: 21000 | G30: 21000 | H30: 21000 | I30: 21000 | J30: 21000 | K30: 21000 | L30: 21000 | M30: 21000 | N30: 21000 | O30: 21000 | P30: 21000 | Q30: 21000 | R30: 21000 | S30: 21000 | T30: 21000 | U30: 21000 | V30: 21000 | W30: 21000 | X30: 21000 | Y30: 21000 | Z30: 0 | AA30: 42000 | AB30: 0 | AC30: 42000 | AD30: 0 | AE30: 21000 | AF30: 42000 | AG30: 21000 | AH30: 21000 | AI30: 21000 | AJ30: 21000 | AK30: 21000 | AL30: 21000 | AM30: 21000 | AN30: 21000 | AO30: 21000 | AP30: 21000 | AQ30: 21000 | AR30: 21000 | AS30: 21000 | AT30: 21000 | AU30: 21000 | AV30: 21000 | AW30: 21000 | AX30: 21000 | AY30: 21000 | AZ30: 21000 | BA30: 21000 | BB30: 21000 | BC30: 21000 | BD30: 21000 | BE30: 21000 | BF30: 21000 | BG30: 21000 | BH30: 0 | BI30: 42000 | BJ30: 21000 | BK30: 21000 | BL30: 21000 | BM30: 21000 | BN30: 0 | BO30: 42000 | BP30: 21000 | BQ30: 21000 | BR30: 21000 | BS30: 21000 | BT30: 21000 | BU30: 21000 | BV30: 21000 | BW30: 21000 | BX30: 21000 | BY30: 21000 | BZ30: 21000 | CA30: 21000 | CB30: 21000 | CC30: 21000 | CD30: 21000 | CE30: 0 | CF30: 42000 | CG30: 21000 | CH30: 21000 | CI30: 21000 | CJ30: 21000 | CK30: 21000 | CL30: 21000 | CM30: 21000 | CN30: 21000 | CO30: 21000 | CP30: 21000 | CQ30: 21000 | CR30: 21000 | CS30: 21000 | CT30: 21000 | CU30: 21000 | CV30: 21000 | CW30: 21000 | CX30: 21000 | CY30: 21000 | CZ30: 21000 | DA30: 21000 | DB30: 21000 | DC30: 21000 | DD30: 21000 | DE30: 21000 | DF30: 21000 | DG30: 21000 | DH30: 21000
A31: 25 | B31: ይድነቃቸው ወ/መስቀል | C31: 21000 | D31: =Sheet3!C27 -> 108 | E31: 21000 | F31: 21000 | G31: 21000 | H31: 21000 | I31: 21000 | J31: 21000 | K31: 21000 | L31: 21000 | M31: 21000 | N31: 21000 | O31: 21000 | P31: 21000 | Q31: 21000 | R31: 21000 | S31: 21000 | T31: 21000 | U31: 21000 | V31: 21000 | W31: 21000 | X31: 21000 | Y31: 21000 | Z31: 21000 | AA31: 21000 | AB31: 21000 | AC31: 21000 | AD31: 21000 | AE31: 21000 | AF31: 21000 | AG31: 21000 | AH31: 21000 | AI31: 21000 | AJ31: 21000 | AK31: 21000 | AL31: 21000 | AM31: 21000 | AN31: 21000 | AO31: 21000 | AP31: 21000 | AQ31: 21000 | AR31: 21000 | AS31: 0 | AT31: 42000 | AU31: 0 | AV31: 42000 | AW31: 21000 | AX31: 0 | AY31: 42000 | AZ31: 21000 | BA31: 21000 | BB31: 21000 | BC31: 21000 | BD31: 21000 | BE31: 0 | BF31: 42000 | BG31: 21000 | BH31: 0 | BI31: 42000 | BJ31: 21000 | BK31: 21000 | BL31: 21000 | BM31: 21000 | BN31: 0 | BO31: 42000 | BP31: 0 | BQ31: 42000 | BR31: 21000 | BS31: 21000 | BT31: 21000 | BU31: 21000 | BV31: 21000 | BW31: 21000 | BX31: 21000 | BY31: 21000 | BZ31: 21000 | CA31: 0 | CB31: 42000 | CC31: 0 | CD31: 42000 | CE31: 21000 | CF31: 21000 | CG31: 0 | CH31: 42000 | CI31: 0 | CJ31: 42000 | CK31: 21000 | CL31: 21000 | CM31: 21000 | CN31: 21000 | CO31: 21000 | CP31: 21000 | CQ31: 0 | CR31: 42000 | CS31: 21000 | CT31: 21000 | CU31: 21000 | CV31: 21000 | CW31: 21000 | CX31: 21000 | CY31: 21000 | CZ31: 21000 | DA31: 21000 | DB31: 21000 | DC31: 21000 | DD31: 21000 | DE31: 21000 | DF31: 21000 | DG31: 21000 | DH31: 21000
A32: 26 | B32: ፈትለወርቅ ታደሰ | C32: 21000 | D32: =Sheet3!C28 -> 108 | E32: 21000 | F32: 21000 | G32: 21000 | H32: 21000 | I32: 21000 | J32: 21000 | K32: 21000 | L32: 21000 | M32: 21000 | N32: 21000 | O32: 21000 | P32: 21000 | Q32: 21000 | R32: 21000 | S32: 21000 | T32: 21000 | U32: 21000 | V32: 21000 | W32: 21000 | X32: 21000 | Y32: 21000 | Z32: 21000 | AA32: 21000 | AB32: 21000 | AC32: 21000 | AD32: 21000 | AE32: 21000 | AF32: 21000 | AG32: 21000 | AH32: 21000 | AI32: 21000 | AJ32: 21000 | AK32: 21000 | AL32: 21000 | AM32: 21000 | AN32: 21000 | AO32: 21000 | AP32: 21000 | AQ32: 21000 | AR32: 21000 | AS32: 0 | AT32: 42000 | AU32: 0 | AV32: 42000 | AW32: 21000 | AX32: 0 | AY32: 42000 | AZ32: 21000 | BA32: 21000 | BB32: 21000 | BC32: 21000 | BD32: 21000 | BE32: 0 | BF32: 42000 | BG32: 21000 | BH32: 0 | BI32: 42000 | BJ32: 21000 | BK32: 21000 | BL32: 21000 | BM32: 21000 | BN32: 0 | BO32: 42000 | BP32: 0 | BQ32: 42000 | BR32: 21000 | BS32: 21000 | BT32: 21000 | BU32: 21000 | BV32: 21000 | BW32: 21000 | BX32: 21000 | BY32: 21000 | BZ32: 21000 | CA32: 0 | CB32: 42000 | CC32: 0 | CD32: 42000 | CE32: 21000 | CF32: 21000 | CG32: 0 | CH32: 42000 | CI32: 0 | CJ32: 42000 | CK32: 21000 | CL32: 21000 | CM32: 21000 | CN32: 21000 | CO32: 21000 | CP32: 21000 | CQ32: 0 | CR32: 42000 | CS32: 21000 | CT32: 21000 | CU32: 21000 | CV32: 21000 | CW32: 21000 | CX32: 21000 | CY32: 21000 | CZ32: 21000 | DA32: 21000 | DB32: 21000 | DC32: 21000 | DD32: 21000 | DE32: 21000 | DF32: 21000 | DG32: 21000 | DH32: 21000
A33: 27 | B33: አንተነህ ግዛዉ | C33: 21000 | D33: =Sheet3!C29 -> 105 | E33: 21000 | F33: 21000 | G33: 21000 | H33: 21000 | I33: 21000 | J33: 21000 | K33: 21000 | L33: 21000 | M33: 21000 | N33: 21000 | O33: 21000 | P33: 21000 | Q33: 21000 | R33: 21000 | S33: 21000 | T33: 21000 | U33: 21000 | V33: 21000 | W33: 21000 | X33: 21000 | Y33: 21000 | Z33: 0 | AA33: 42000 | AB33: 21000 | AC33: 21000 | AD33: 21000 | AE33: 0 | AF33: 21000 | AG33: 42000 | AH33: 21000 | AI33: 21000 | AJ33: 0 | AK33: 42000 | AL33: 21000 | AM33: 21000 | AN33: 21000 | AO33: 21000 | AP33: 21000 | AQ33: 0 | AR33: 42000 | AS33: 21000 | AT33: 0 | AU33: 42000 | AV33: 21000 | AW33: 21000 | AX33: 21000 | AY33: 21000 | AZ33: 0 | BA33: 21000 | BB33: 21000 | BC33: 21000 | BD33: 21000 | BE33: 21000 | BF33: 21000 | BG33: 21000 | BH33: 21000 | BI33: 21000 | BJ33: 21000 | BK33: 21000 | BL33: 21000 | BM33: 21000 | BN33: 21000 | BO33: 21000 | BP33: 0 | BQ33: 42000 | BR33: 21000 | BS33: 21000 | BU33: 42000 | BV33: 0 | BW33: 42000 | BX33: 21000 | BY33: 21000 | BZ33: 21000 | CA33: 21000 | CB33: 21000 | CC33: 21000 | CD33: 21000 | CE33: 0 | CF33: 21000 | CG33: 21000 | CH33: 21000 | CI33: 0 | CJ33: 42000 | CK33: 21000 | CL33: 21000 | CM33: 21000 | CN33: 21000 | CO33: 21000 | CP33: 21000 | CQ33: 21000 | CR33: 21000 | CS33: 21000 | CT33: 21000 | CU33: 21000 | CV33: 21000 | CW33: 21000 | CX33: 0 | CY33: 42000 | CZ33: 0 | DA33: 42000 | DB33: 21000 | DC33: 0 | DD33: 0 | DE33: 42000 | DF33: 21000 | DG33: 21000 | DH33: 21000
A34: 28 | B34: ግርማ አበበ | C34: 21000 | D34: =Sheet3!C30 -> 0 | E34: 0 | F34: 0 | G34: 0 | H34: 0 | I34: 0 | J34: 0 | K34: 0 | L34: 0 | M34: 0 | N34: 0 | O34: 0 | P34: 0 | Q34: 0 | R34: 0 | S34: 0 | T34: 0 | U34: 0 | V34: 0 | W34: 0 | X34: 0 | Y34: 0 | Z34: 0 | AA34: 0 | AB34: 0 | AC34: 0 | AD34: 0 | AE34: 0 | AF34: 0 | AG34: 0 | AH34: 0 | AI34: 0 | AJ34: 0 | AK34: 0 | AL34: 0 | AM34: 0 | AN34: 0 | AO34: 0 | AP34: 0 | AQ34: 0 | AR34: 0 | AS34: 0 | AT34: 0 | AU34: 0 | AV34: 0 | AW34: 0 | AX34: 0 | AY34: 0 | AZ34: 0 | BA34: 0 | BB34: 0 | BC34: 0 | BD34: 0 | BE34: 0 | BF34: 0 | BG34: 0 | BH34: 0 | BI34: 0 | BJ34: 0 | BK34: 0 | BL34: 0 | BM34: 0 | BN34: 0 | BO34: 0 | BP34: 0 | BQ34: 0 | BR34: 0 | BS34: 0 | BT34: 0 | BV34: 0 | BW34: 0 | BX34: 0 | BY34: 0 | BZ34: 0 | CA34: 0 | CB34: 0 | CC34: 0 | CD34: 0 | CF34: 0 | CG34: 0 | CH34: 0 | CI34: 0 | CJ34: 0 | CK34: 0 | CL34: 0 | CM34: 0 | CN34: 0 | CO34: 0 | CP34: 0 | CQ34: 0 | CR34: 0 | CS34: 0 | CT34: 0 | CU34: 0 | CV34: 0 | CW34: 0 | CX34: 0 | CY34: 0 | CZ34: 0 | DA34: 0 | DB34: 0 | DC34: 0 | DD34: 0 | DE34: 0 | DF34: 0
A35: 29 | B35: መስፍን መንግስቱ | C35: 21000 | D35: =Sheet3!C31 -> 104 | E35: 21000 | F35: 21000 | G35: 21000 | H35: 21000 | I35: 21000 | J35: 21000 | K35: 21000 | L35: 21000 | M35: 21000 | N35: 21000 | O35: 21000 | P35: 21000 | Q35: 21000 | R35: 21000 | S35: 21000 | T35: 21000 | U35: 21000 | V35: 21000 | W35: 21000 | X35: 21000 | Y35: 21000 | Z35: 21000 | AA35: 21000 | AB35: 21000 | AC35: 21000 | AD35: 21000 | AE35: 0 | AF35: 42000 | AG35: 21000 | AH35: 21000 | AI35: 21000 | AJ35: 21000 | AK35: 21000 | AL35: 21000 | AM35: 21000 | AN35: 21000 | AO35: 21000 | AP35: 21000 | AQ35: 21000 | AR35: 21000 | AS35: 21000 | AT35: 21000 | AU35: 21000 | AV35: 21000 | AW35: 21000 | AX35: 21000 | AY35: 21000 | AZ35: 21000 | BA35: 21000 | BB35: 21000 | BC35: 0 | BD35: 42000 | BE35: 21000 | BF35: 21000 | BG35: 21000 | BH35: 0 | BI35: 21000 | BJ35: 21000 | BK35: 42000 | BL35: 0 | BM35: 42000 | BN35: 0 | BO35: 21000 | BP35: 0 | BQ35: 42000 | BR35: 21000 | BS35: 0 | BT35: 42000 | BU35: 21000 | BV35: 0 | BW35: 0 | BX35: 63000 | BY35: 0 | BZ35: 0 | CA35: 42000 | CB35: 42000 | CC35: 21000 | CD35: 21000 | CF35: 42000 | CG35: 0 | CH35: 63000 | CI35: 0 | CJ35: 42000 | CK35: 21000 | CL35: 21000 | CM35: 0 | CN35: 42000 | CO35: 21000 | CP35: 21000 | CQ35: 21000 | CR35: 0 | CS35: 42000 | CT35: 21000 | CU35: 0 | CV35: 0 | CW35: 0 | CX35: 0 | CY35: 0 | CZ35: 0 | DA35: 63000 | DB35: 84000 | DC35: 0 | DD35: 0 | DE35: 0 | DF35: 0 | DG35: 63000
A36: 30 | B36: እሱባለው ስለሺ | C36: 21000 | D36: =Sheet3!C32 -> 92 | E36: 21000 | F36: 21000 | G36: 21000 | H36: 21000 | I36: 21000 | J36: 21000 | K36: 21000 | L36: 21000 | M36: 21000 | N36: 21000 | O36: 21000 | P36: 21000 | Q36: 21000 | R36: 21000 | S36: 21000 | T36: 21000 | U36: 21000 | V36: 21000 | W36: 21000 | X36: 21000 | Y36: 21000 | Z36: 21000 | AA36: 21000 | AB36: 21000 | AC36: 21000 | AD36: 21000 | AE36: 21000 | AF36: 21000 | AG36: 21000 | AH36: 21000 | AI36: 21000 | AJ36: 21000 | AK36: 21000 | AL36: 21000 | AM36: 21000 | AN36: 21000 | AO36: 21000 | AP36: 21000 | AQ36: 21000 | AR36: 21000 | AS36: 21000 | AT36: 21000 | AU36: 21000 | AV36: 21000 | AW36: 21000 | AX36: 21000 | AY36: 21000 | AZ36: 21000 | BA36: 21000 | BB36: 21000 | BC36: 21000 | BD36: 21000 | BE36: 21000 | BF36: 21000 | BG36: 21000 | BH36: 21000 | BI36: 21000 | BJ36: 21000 | BK36: 21000 | BL36: 21000 | BM36: 21000 | BN36: 0 | BO36: 21000 | BP36: 21000 | BR36: 42000 | BS36: 21000 | BU36: 21000 | BV36: 21000 | BW36: 21000 | BX36: 0 | BY36: 42000 | BZ36: 0 | CA36: 0 | CB36: 42000 | CC36: 0 | CD36: 42000 | CF36: 42000 | CG36: 0 | CH36: 42000 | CI36: 0 | CJ36: 42000 | CK36: 0 | CL36: 0 | CM36: 42000 | CN36: 0 | CO36: 0 | CP36: 42000 | CQ36: 0 | CR36: 21000 | CS36: 0 | CT36: 0 | CU36: 0 | CV36: 42000 | CW36: 42000 | CX36: 0 | CY36: 21000 | CZ36: 0 | DA36: 21000 | DB36: 0 | DC36: 0 | DD36: 0 | DE36: 0 | DF36: 0
A37: 31 | B37: ከፈለኝ ፃዲቁ | C37: 21000 | D37: =Sheet3!C33 -> 0 | E37: 0 | F37: 0 | G37: 0 | H37: 0 | I37: 0 | J37: 0 | K37: 0 | L37: 0 | M37: 0 | N37: 0 | O37: 0 | P37: 0 | Q37: 0 | R37: 0 | S37: 0 | T37: 0 | U37: 0 | V37: 0 | W37: 0 | X37: 0 | Y37: 0 | Z37: 0 | AA37: 0 | AB37: 0 | AC37: 0 | AD37: 0 | AE37: 0 | AF37: 0 | AG37: 0 | AH37: 0 | AI37: 0 | AJ37: 0 | AK37: 0 | AL37: 0 | AM37: 0 | AN37: 0 | AO37: 0 | AP37: 0 | AQ37: 0 | AR37: 0 | AS37: 0 | AT37: 0 | AU37: 0 | AV37: 0 | AW37: 0 | AX37: 0 | AY37: 0 | AZ37: 0 | BA37: 0 | BB37: 0 | BC37: 0 | BD37: 0 | BE37: 0 | BF37: 0 | BG37: 0 | BH37: 0 | BI37: 0 | BJ37: 0 | BK37: 0 | BL37: 0 | BM37: 0 | BN37: 0 | BO37: 0 | BP37: 0 | BQ37: 0 | BR37: 0 | BS37: 0 | BT37: 0 | BV37: 0 | BW37: 0 | BX37: 0 | BY37: 0 | BZ37: 0 | CA37: 0 | CB37: 0 | CC37: 0 | CD37: 0 | CF37: 0 | CG37: 0 | CH37: 0 | CI37: 0 | CJ37: 0 | CK37: 0 | CL37: 0 | CM37: 0 | CN37: 0 | CO37: 0 | CP37: 0 | CQ37: 0 | CR37: 0 | CS37: 0 | CT37: 0 | CU37: 0 | CV37: 0 | CW37: 0 | CX37: 0 | CY37: 0 | CZ37: 0 | DA37: 0 | DB37: 0 | DC37: 0 | DD37: 0 | DE37: 0 | DF37: 0
A38: 32 | B38: ዳንኤል ጎሌ | C38: 21000 | D38: =Sheet3!C34 -> 108 | E38: 21000 | F38: 21000 | G38: 21000 | H38: 21000 | I38: 21000 | J38: 21000 | K38: 21000 | L38: 21000 | M38: 21000 | N38: 21000 | O38: 21000 | P38: 21000 | Q38: 21000 | R38: 21000 | S38: 21000 | T38: 21000 | U38: 21000 | V38: 21000 | W38: 21000 | X38: 21000 | Y38: 21000 | Z38: 21000 | AA38: 21000 | AB38: 21000 | AC38: 21000 | AD38: 21000 | AE38: 21000 | AF38: 21000 | AG38: 21000 | AH38: 21000 | AI38: 21000 | AJ38: 21000 | AK38: 21000 | AL38: 21000 | AM38: 21000 | AN38: 21000 | AO38: 21000 | AP38: 21000 | AQ38: 21000 | AR38: 21000 | AS38: 21000 | AT38: 21000 | AU38: 21000 | AV38: 21000 | AW38: 21000 | AX38: 21000 | AY38: 21000 | AZ38: 21000 | BA38: 21000 | BB38: 21000 | BC38: 21000 | BD38: 21000 | BE38: 21000 | BF38: 21000 | BG38: 21000 | BH38: 21000 | BI38: 21000 | BJ38: 21000 | BK38: 21000 | BL38: 21000 | BM38: 21000 | BN38: 21000 | BO38: 21000 | BP38: 21000 | BQ38: 21000 | BR38: 21000 | BS38: 21000 | BT38: 21000 | BU38: 21000 | BV38: 21000 | BW38: 21000 | BX38: 21000 | BY38: 21000 | BZ38: 21000 | CA38: 21000 | CB38: 21000 | CC38: 21000 | CD38: 21000 | CE38: 21000 | CF38: 21000 | CG38: 21000 | CH38: 0 | CI38: 42000 | CJ38: 21000 | CK38: 21000 | CL38: 21000 | CM38: 21000 | CN38: 21000 | CO38: 21000 | CP38: 21000 | CQ38: 21000 | CR38: 21000 | CS38: 21000 | CT38: 21000 | CU38: 21000 | CV38: 21000 | CW38: 21000 | CX38: 21000 | CY38: 21000 | CZ38: 21000 | DA38: 21000 | DB38: 21000 | DC38: 21000 | DD38: 21000 | DE38: 21000 | DF38: 21000 | DG38: 21000 | DH38: 21000
A39: 33 | B39: አየነዉ ፀጋዩ | C39: 21000 | D39: =Sheet3!C35 -> 105 | E39: 21000 | F39: 21000 | G39: 21000 | H39: 21000 | I39: 21000 | J39: 21000 | K39: 21000 | L39: 21000 | M39: 21000 | N39: 21000 | O39: 21000 | P39: 21000 | Q39: 21000 | R39: 21000 | S39: 21000 | T39: 21000 | U39: 21000 | V39: 21000 | W39: 21000 | X39: 21000 | Y39: 21000 | Z39: 21000 | AA39: 21000 | AB39: 21000 | AC39: 21000 | AD39: 21000 | AE39: 21000 | AF39: 21000 | AG39: 21000 | AH39: 21000 | AI39: 21000 | AJ39: 21000 | AK39: 21000 | AL39: 21000 | AM39: 21000 | AN39: 21000 | AO39: 21000 | AP39: 21000 | AQ39: 21000 | AR39: 21000 | AS39: 21000 | AT39: 21000 | AU39: 21000 | AV39: 21000 | AW39: 21000 | AX39: 21000 | AY39: 21000 | AZ39: 21000 | BA39: 21000 | BB39: 21000 | BC39: 21000 | BD39: 21000 | BE39: 21000 | BF39: 21000 | BG39: 0 | BH39: 42000 | BI39: 0 | BJ39: 42000 | BK39: 21000 | BL39: 21000 | BM39: 21000 | BN39: 0 | BO39: 42000 | BP39: 21000 | BQ39: 21000 | BS39: 42000 | BT39: 21000 | BV39: 42000 | BW39: 0 | BX39: 42000 | BY39: 21000 | BZ39: 21000 | CA39: 0 | CB39: 0 | CC39: 63000 | CD39: 0 | CF39: 42000 | CG39: 21000 | CH39: 21000 | CI39: 0 | CJ39: 0 | CK39: 63000 | CL39: 0 | CM39: 0 | CN39: 42000 | CO39: 0 | CP39: 42000 | CQ39: 0 | CR39: 42000 | CS39: 0 | CT39: 42000 | CU39: 0 | CV39: 0 | CW39: 63000 | CX39: 0 | CY39: 0 | CZ39: 0 | DA39: 84000 | DB39: 0 | DC39: 0 | DD39: 0 | DE39: 0 | DF39: 84000 | DG39: 42000
A40: 34 | B40: ደሊል ፍሬው | C40: 21000 | D40: =Sheet3!C36 -> 108 | E40: 21000 | F40: 21000 | G40: 21000 | H40: 21000 | I40: 21000 | J40: 21000 | K40: 21000 | L40: 21000 | M40: 21000 | N40: 21000 | O40: 21000 | P40: 21000 | Q40: 21000 | R40: 21000 | S40: 21000 | T40: 21000 | U40: 21000 | V40: 21000 | W40: 21000 | X40: 21000 | Y40: 21000 | Z40: 21000 | AA40: 21000 | AB40: 0 | AC40: 42000 | AD40: 21000 | AE40: 21000 | AF40: 21000 | AG40: 21000 | AH40: 21000 | AI40: 21000 | AJ40: 21000 | AK40: 21000 | AL40: 21000 | AM40: 21000 | AN40: 21000 | AO40: 21000 | AP40: 21000 | AQ40: 21000 | AR40: 21000 | AS40: 21000 | AT40: 21000 | AU40: 21000 | AV40: 21000 | AW40: 21000 | AX40: 21000 | AY40: 21000 | AZ40: 21000 | BA40: 21000 | BB40: 21000 | BC40: 21000 | BD40: 21000 | BE40: 21000 | BF40: 21000 | BG40: 21000 | BH40: 21000 | BI40: 21000 | BJ40: 21000 | BK40: 21000 | BL40: 21000 | BM40: 21000 | BN40: 21000 | BO40: 21000 | BP40: 21000 | BQ40: 21000 | BR40: 21000 | BS40: 21000 | BT40: 21000 | BU40: 21000 | BV40: 21000 | BW40: 21000 | BX40: 21000 | BY40: 21000 | BZ40: 21000 | CA40: 21000 | CB40: 21000 | CC40: 21000 | CD40: 21000 | CE40: 21000 | CF40: 21000 | CG40: 21000 | CH40: 21000 | CI40: 21000 | CJ40: 21000 | CK40: 21000 | CL40: 21000 | CM40: 21000 | CN40: 21000 | CO40: 21000 | CP40: 21000 | CQ40: 21000 | CR40: 21000 | CS40: 21000 | CT40: 0 | CU40: 42000 | CV40: 21000 | CW40: 21000 | CX40: 21000 | CY40: 21000 | CZ40: 21000 | DA40: 21000 | DB40: 21000 | DC40: 21000 | DD40: 21000 | DE40: 21000 | DF40: 21000 | DG40: 21000 | DH40: 21000
...

Sheet ቦኖ
A1: =ዕቁብ!A1 -> ዕጣ ቁጥር | B1: =ዕቁብ!B1 -> ስም | D1: 1 | E1: =D1+1 -> 2 | F1: =E1+1 -> 3 | G1: =F1+1 -> 4 | H1: =G1+1 -> 5 | I1: =H1+1 -> 6 | J1: =I1+1 -> 7 | K1: =J1+1 -> 8 | L1: =K1+1 -> 9 | ... DQ1: =DP1+1 -> 118
C2: =ዕቁብ!C1 -> ክፍያ መጠን | D2: =ዕቁብ!E2 -> 44871 | E2: =ዕቁብ!F2 -> 44878 | F2: =ዕቁብ!G2 -> 44885 | G2: =ዕቁብ!H2 -> 44892 | H2: =ዕቁብ!I2 -> 44899 | I2: =ዕቁብ!J2 -> 44906 | J2: =ዕቁብ!K2 -> 44913 | K2: =ዕቁብ!L2 -> 44920 | ... DQ2: =ዕቁብ!DR2 -> 45690
D3: =D137 -> 107 | E3: =E137 -> 106.5 | F3: =F137 -> 106.5 | G3: =G137 -> 106.5 | H3: =H137 -> 106.5 | I3: =I137 -> 106.5 | J3: =J137 -> 106.5 | K3: =K137 -> 106.5 | ... DQ3: =DQ137 -> 0
A4: =ዕቁብ!A6 -> 1 | B4: =ዕቁብ!B6 -> መስፍን ሀ/ማሪያም | C4: =ዕቁብ!C6 -> 21000 | D4: =IF((ዕቁብ!E6/ቦኖ!$C$4>0),1,0) -> 1 | E4: =IF((ዕቁብ!F6/ቦኖ!$C$4>0),1,0) -> 1 | F4: =IF((ዕቁብ!G6/ቦኖ!$C$4>0),1,0) -> 1 | G4: =IF((ዕቁብ!H6/ቦኖ!$C$4>0),1,0) -> 1 | H4: =IF((ዕቁብ!I6/ቦኖ!$C$4>0),1,0) -> 1 | I4: =IF((ዕቁብ!J6/ቦኖ!$C$4>0),1,0) -> 1 | J4: =IF((ዕቁብ!K6/ቦኖ!$C$4>0),1,0) -> 1 | K4: =IF((ዕቁብ!L6/ቦኖ!$C$4>0),1,0) -> 1 | ... DQ4: =IF((ዕቁብ!DR6/ቦኖ!$C$4>0),1,0) -> 0
A5: =ዕቁብ!A7 -> 2 | B5: =ዕቁብ!B7 -> ዓማኑኤል አላሮ | C5: =ዕቁብ!C7 -> 21000 | D5: =IF((ዕቁብ!E7/ቦኖ!$C$4>0),1,0) -> 1 | E5: =IF((ዕቁብ!F7/ቦኖ!$C$4>0),1,0) -> 1 | F5: =IF((ዕቁብ!G7/ቦኖ!$C$4>0),1,0) -> 1 | G5: =IF((ዕቁብ!H7/ቦኖ!$C$4>0),1,0) -> 1 | H5: =IF((ዕቁብ!I7/ቦኖ!$C$4>0),1,0) -> 1 | I5: =IF((ዕቁብ!J7/ቦኖ!$C$4>0),1,0) -> 1 | J5: =IF((ዕቁብ!K7/ቦኖ!$C$4>0),1,0) -> 1 | K5: =IF((ዕቁብ!L7/ቦኖ!$C$4>0),1,0) -> 1 | ... DQ5: =IF((ዕቁብ!DR7/ቦኖ!$C$4>0),1,0) -> 0
A6: =ዕቁብ!A8 -> 3 | B6: =ዕቁብ!B8 -> ብርሃኑ ማሩ | C6: =ዕቁብ!C8 -> 21000 | D6: =IF((ዕቁብ!E8/ቦኖ!$C$4>0),1,0) -> 1 | E6: =IF((ዕቁብ!F8/ቦኖ!$C$4>0),1,0) -> 1 | F6: =IF((ዕቁብ!G8/ቦኖ!$C$4>0),1,0) -> 1 | G6: =IF((ዕቁብ!H8/ቦኖ!$C$4>0),1,0) -> 1 | H6: =IF((ዕቁብ!I8/ቦኖ!$C$4>0),1,0) -> 1 | I6: =IF((ዕቁብ!J8/ቦኖ!$C$4>0),1,0) -> 1 | J6: =IF((ዕቁብ!K8/ቦኖ!$C$4>0),1,0) -> 1 | K6: =IF((ዕቁብ!L8/ቦኖ!$C$4>0),1,0) -> 1 | ... DQ6: =IF((ዕቁብ!DR8/ቦኖ!$C$4>0),1,0) -> 0
A7: =ዕቁብ!A9 -> 4 | B7: =ዕቁብ!B9 -> ከፈለኝ ፃዲቁ | C7: =ዕቁብ!C9 -> 21000 | D7: =IF((ዕቁብ!E9/ቦኖ!$C$4>0),1,0) -> 0 | E7: =IF((ዕቁብ!F9/ቦኖ!$C$4>0),1,0) -> 0 | F7: =IF((ዕቁብ!G9/ቦኖ!$C$4>0),1,0) -> 0 | G7: =IF((ዕቁብ!H9/ቦኖ!$C$4>0),1,0) -> 0 | H7: =IF((ዕቁብ!I9/ቦኖ!$C$4>0),1,0) -> 0 | I7: =IF((ዕቁብ!J9/ቦኖ!$C$4>0),1,0) -> 0 | J7: =IF((ዕቁብ!K9/ቦኖ!$C$4>0),1,0) -> 0 | K7: =IF((ዕቁብ!L9/ቦኖ!$C$4>0),1,0) -> 0 | ... DQ7: =IF((ዕቁብ!DR9/ቦኖ!$C$4>0),1,0) -> 0
A8: =ዕቁብ!A10 -> 5 | B8: =ዕቁብ!B10 -> አስፈው ወርጂ | C8: =ዕቁብ!C10 -> 21000 | D8: =IF((ዕቁብ!E10/ቦኖ!$C$4>0),1,0) -> 1 | E8: =IF((ዕቁብ!F10/ቦኖ!$C$4>0),1,0) -> 1 | F8: =IF((ዕቁብ!G10/ቦኖ!$C$4>0),1,0) -> 1 | G8: =IF((ዕቁብ!H10/ቦኖ!$C$4>0),1,0) -> 1 | H8: =IF((ዕቁብ!I10/ቦኖ!$C$4>0),1,0) -> 1 | I8: =IF((ዕቁብ!J10/ቦኖ!$C$4>0),1,0) -> 1 | J8: =IF((ዕቁብ!K10/ቦኖ!$C$4>0),1,0) -> 1 | K8: =IF((ዕቁብ!L10/ቦኖ!$C$4>0),1,0) -> 1 | ... DQ8: =IF((ዕቁብ!DR10/ቦኖ!$C$4>0),1,0) -> 0
A9: =ዕቁብ!A11 -> 6 | B9: =ዕቁብ!B11 -> ከተማ ለማ | C9: =ዕቁብ!C11 -> 21000 | D9: =IF((ዕቁብ!E11/ቦኖ!$C$4>0),1,0) -> 1 | E9: =IF((ዕቁብ!F11/ቦኖ!$C$4>0),1,0) -> 1 | F9: =IF((ዕቁብ!G11/ቦኖ!$C$4>0),1,0) -> 1 | G9: =IF((ዕቁብ!H11/ቦኖ!$C$4>0),1,0) -> 1 | H9: =IF((ዕቁብ!I11/ቦኖ!$C$4>0),1,0) -> 1 | I9: =IF((ዕቁብ!J11/ቦኖ!$C$4>0),1,0) -> 1 | J9: =IF((ዕቁብ!K11/ቦኖ!$C$4>0),1,0) -> 1 | K9: =IF((ዕቁብ!L11/ቦኖ!$C$4>0),1,0) -> 1 | ... DQ9: =IF((ዕቁብ!DR11/ቦኖ!$C$4>0),1,0) -> 0
A10: =ዕቁብ!A12 -> 7 | B10: =ዕቁብ!B12 -> ጥላነሽ ከበደ | C10: =ዕቁብ!C12 -> 21000 | D10: =IF((ዕቁብ!E12/ቦኖ!$C$4>0),1,0) -> 1 | E10: =IF((ዕቁብ!F12/ቦኖ!$C$4>0),1,0) -> 1 | F10: =IF((ዕቁብ!G12/ቦኖ!$C$4>0),1,0) -> 1 | G10: =IF((ዕቁብ!H12/ቦኖ!$C$4>0),1,0) -> 1 | H10: =IF((ዕቁብ!I12/ቦኖ!$C$4>0),1,0) -> 1 | I10: =IF((ዕቁብ!J12/ቦኖ!$C$4>0),1,0) -> 1 | J10: =IF((ዕቁብ!K12/ቦኖ!$C$4>0),1,0) -> 1 | K10: =IF((ዕቁብ!L12/ቦኖ!$C$4>0),1,0) -> 1 | ... DQ10: =IF((ዕቁብ!DR12/ቦኖ!$C$4>0),1,0) -> 0
A11: =ዕቁብ!A13 -> 8 | B11: =ዕቁብ!B13 -> ሲሳይ ባህሩ | C11: =ዕቁብ!C13 -> 21000 | D11: =IF((ዕቁብ!E13/ቦኖ!$C$4>0),1,0) -> 1 | E11: =IF((ዕቁብ!F13/ቦኖ!$C$4>0),1,0) -> 1 | F11: =IF((ዕቁብ!G13/ቦኖ!$C$4>0),1,0) -> 1 | G11: =IF((ዕቁብ!H13/ቦኖ!$C$4>0),1,0) -> 1 | H11: =IF((ዕቁብ!I13/ቦኖ!$C$4>0),1,0) -> 1 | I11: =IF((ዕቁብ!J13/ቦኖ!$C$4>0),1,0) -> 1 | J11: =IF((ዕቁብ!K13/ቦኖ!$C$4>0),1,0) -> 1 | K11: =IF((ዕቁብ!L13/ቦኖ!$C$4>0),1,0) -> 1 | ... DQ11: =IF((ዕቁብ!DR13/ቦኖ!$C$4>0),1,0) -> 0
A12: =ዕቁብ!A14 -> 9 | B12: =ዕቁብ!B14 -> ሲንታየሁ ካሳ | C12: =ዕቁብ!C14 -> 21000 | D12: =IF((ዕቁብ!E14/ቦኖ!$C$4>0),1,0) -> 1 | E12: =IF((ዕቁብ!F14/ቦኖ!$C$4>0),1,0) -> 1 | F12: =IF((ዕቁብ!G14/ቦኖ!$C$4>0),1,0) -> 1 | G12: =IF((ዕቁብ!H14/ቦኖ!$C$4>0),1,0) -> 1 | H12: =IF((ዕቁብ!I14/ቦኖ!$C$4>0),1,0) -> 1 | I12: =IF((ዕቁብ!J14/ቦኖ!$C$4>0),1,0) -> 1 | J12: =IF((ዕቁብ!K14/ቦኖ!$C$4>0),1,0) -> 1 | K12: =IF((ዕቁብ!L14/ቦኖ!$C$4>0),1,0) -> 1 | ... DQ12: =IF((ዕቁብ!DR14/ቦኖ!$C$4>0),1,0) -> 0
A13: =ዕቁብ!A15 -> 10 | B13: =ዕቁብ!B15 -> ጥላነሽ ከበደ | C13: =ዕቁብ!C15 -> 21000 | D13: =IF((ዕቁብ!E15/ቦኖ!$C$4>0),1,0) -> 1 | E13: =IF((ዕቁብ!F15/ቦኖ!$C$4>0),1,0) -> 1 | F13: =IF((ዕቁብ!G15/ቦኖ!$C$4>0),1,0) -> 1 | G13: =IF((ዕቁብ!H15/ቦኖ!$C$4>0),1,0) -> 1 | H13: =IF((ዕቁብ!I15/ቦኖ!$C$4>0),1,0) -> 1 | I13: =IF((ዕቁብ!J15/ቦኖ!$C$4>0),1,0) -> 1 | J13: =IF((ዕቁብ!K15/ቦኖ!$C$4>0),1,0) -> 1 | K13: =IF((ዕቁብ!L15/ቦኖ!$C$4>0),1,0) -> 1 | ... DQ13: =IF((ዕቁብ!DR15/ቦኖ!$C$4>0),1,0) -> 0
A14: =ዕቁብ!A16 -> 11 | B14: =ዕቁብ!B16 -> ሄኖክ በቀለ | C14: =ዕቁብ!C16 -> 21000 | D14: =IF((ዕቁብ!E16/ቦኖ!$C$4>0),1,0) -> 1 | E14: =IF((ዕቁብ!F16/ቦኖ!$C$4>0),1,0) -> 1 | F14: =IF((ዕቁብ!G16/ቦኖ!$C$4>0),1,0) -> 1 | G14: =IF((ዕቁብ!H16/ቦኖ!$C$4>0),1,0) -> 1 | H14: =IF((ዕቁብ!I16/ቦኖ!$C$4>0),1,0) -> 1 | I14: =IF((ዕቁብ!J16/ቦኖ!$C$4>0),1,0) -> 1 | J14: =IF((ዕቁብ!K16/ቦኖ!$C$4>0),1,0) -> 1 | K14: =IF((ዕቁብ!L16/ቦኖ!$C$4>0),1,0) -> 1 | ... DQ14: =IF((ዕቁብ!DR16/ቦኖ!$C$4>0),1,0) -> 0
A15: =ዕቁብ!A17 -> 12 | B15: =ዕቁብ!B17 -> ሀብታሙ ፃዲቁ | C15: =ዕቁብ!C17 -> 21000 | D15: =IF((ዕቁብ!E17/ቦኖ!$C$4>0),1,0) -> 0 | E15: =IF((ዕቁብ!F17/ቦኖ!$C$4>0),1,0) -> 0 | F15: =IF((ዕቁብ!G17/ቦኖ!$C$4>0),1,0) -> 0 | G15: =IF((ዕቁብ!H17/ቦኖ!$C$4>0),1,0) -> 0 | H15: =IF((ዕቁብ!I17/ቦኖ!$C$4>0),1,0) -> 0 | I15: =IF((ዕቁብ!J17/ቦኖ!$C$4>0),1,0) -> 0 | J15: =IF((ዕቁብ!K17/ቦኖ!$C$4>0),1,0) -> 0 | K15: =IF((ዕቁብ!L17/ቦኖ!$C$4>0),1,0) -> 0 | ... DQ15: =IF((ዕቁብ!DR17/ቦኖ!$C$4>0),1,0) -> 0
... A21: =ዕቁብ!A23 -> 18 | B21: =ዕቁብ!B23 -> ህዝቄል ጴጥሮስ | C21: =ዕቁብ!C23 -> 21000 | D21: =IF((ዕቁብ!E23/ቦኖ!$C$4>0),1,0) -> 1 | E21: =IF((ዕቁብ!F23/ቦኖ!$C$4>0),1,0) -> 1 | F21: =IF((ዕቁብ!G23/ቦኖ!$C$4>0),1,0) -> 1 | G21: =IF((ዕቁብ!H23/ቦኖ!$C$4>0),1,0) -> 1 | H21: =IF((ዕቁብ!I23/ቦኖ!$C$4>0),1,0) -> 1 | I21: =IF((ዕቁብ!J23/ቦኖ!$C$4>0),1,0) -> 1 | J21: =IF((ዕቁብ!K23/ቦኖ!$C$4>0),1,0) -> 1 | K21: =IF((ዕቁብ!L23/ቦኖ!$C$4>0),1,0) -> 1 | ... DQ21: =IF((ዕቁብ!DR23/ቦኖ!$C$4>0),1,0) -> 0
A22: =ዕቁብ!A24 -> 19 | B22: =ዕቁብ!B24 -> አንተነህ ግዛዉ | C22: =ዕቁብ!C24 -> 10500 | D22: =IF((ዕቁብ!E24/ቦኖ!$C$4>0),(1/2),0) -> 0.5 | E22: =IF((ዕቁብ!F24/ቦኖ!$C$4>0),(1/2),0) -> 0.5 | F22: =IF((ዕቁብ!G24/ቦኖ!$C$4>0),(1/2),0) -> 0.5 | G22: =IF((ዕቁብ!H24/ቦኖ!$C$4>0),(1/2),0) -> 0.5 | H22: =IF((ዕቁብ!I24/ቦኖ!$C$4>0),(1/2),0) -> 0.5 | I22: =IF((ዕቁብ!J24/ቦኖ!$C$4>0),(1/2),0) -> 0.5 | J22: =IF((ዕቁብ!K24/ቦኖ!$C$4>0),(1/2),0) -> 0.5 | K22: =IF((ዕቁብ!L24/ቦኖ!$C$4>0),(1/2),0) -> 0.5 | ... DQ22: =IF((ዕቁብ!DR24/ቦኖ!$C$4>0),(1/2),0) -> 0
A23: =ዕቁብ!A25 -> 19 | B23: =ዕቁብ!B25 -> አለማየሁ ገዛህኝ | C23: =ዕቁብ!C25 -> 10500 | D23: =IF((ዕቁብ!E25/ቦኖ!$C$4>0),(1/2),0) -> 0.5 | E23: =IF((ዕቁብ!F25/ቦኖ!$C$4>0),(1/2),0) -> 0.5 | F23: =IF((ዕቁብ!G25/ቦኖ!$C$4>0),(1/2),0) -> 0.5 | G23: =IF((ዕቁብ!H25/ቦኖ!$C$4>0),(1/2),0) -> 0.5 | H23: =IF((ዕቁብ!I25/ቦኖ!$C$4>0),(1/2),0) -> 0.5 | I23: =IF((ዕቁብ!J25/ቦኖ!$C$4>0),(1/2),0) -> 0.5 | J23: =IF((ዕቁብ!K25/ቦኖ!$C$4>0),(1/2),0) -> 0.5 | K23: =IF((ዕቁብ!L25/ቦኖ!$C$4>0),(1/2),0) -> 0.5 | ... DQ23: =IF((ዕቁብ!DR25/ቦኖ!$C$4>0),(1/2),0) -> 0
A24: =ዕቁብ!A26 -> 20 | B24: =ዕቁብ!B26 -> ሻምበል ቦንጃ | C24: =ዕቁብ!C26 -> 21000 | D24: =IF((ዕቁብ!E26/ቦኖ!$C$4>0),1,0) -> 1 | E24: =IF((ዕቁብ!F26/ቦኖ!$C$4>0),1,0) -> 1 | F24: =IF((ዕቁብ!G26/ቦኖ!$C$4>0),1,0) -> 1 | G24: =IF((ዕቁብ!H26/ቦኖ!$C$4>0),1,0) -> 1 | H24: =IF((ዕቁብ!I26/ቦኖ!$C$4>0),1,0) -> 1 | I24: =IF((ዕቁብ!J26/ቦኖ!$C$4>0),1,0) -> 1 | J24: =IF((ዕቁብ!K26/ቦኖ!$C$4>0),1,0) -> 1 | K24: =IF((ዕቁብ!L26/ቦኖ!$C$4>0),1,0) -> 1 | ... DQ24: =IF((ዕቁብ!DR26/ቦኖ!$C$4>0),1,0) -> 0
A25: =ዕቁብ!A27 -> 21 | B25: =ዕቁብ!B27 -> ማተጎ አመኖ | C25: =ዕቁብ!C27 -> 21000 | D25: =IF((ዕቁብ!E27/ቦኖ!$C$4>0),1,0) -> 1 | E25: =IF((ዕቁብ!F27/ቦኖ!$C$4>0),1,0) -> 1 | F25: =IF((ዕቁብ!G27/ቦኖ!$C$4>0),1,0) -> 1 | G25: =IF((ዕቁብ!H27/ቦኖ!$C$4>0),1,0) -> 1 | H25: =IF((ዕቁብ!I27/ቦኖ!$C$4>0),1,0) -> 1 | I25: =IF((ዕቁብ!J27/ቦኖ!$C$4>0),1,0) -> 1 | J25: =IF((ዕቁብ!K27/ቦኖ!$C$4>0),1,0) -> 1 | K25: =IF((ዕቁብ!L27/ቦኖ!$C$4>0),1,0) -> 1 | ... DQ25: =IF((ዕቁብ!DR27/ቦኖ!$C$4>0),1,0) -> 0
